Workbook

Sheet CUSTOS
A1: OUTUBRO - 2025
A3: PREV | B3: (Tudo)
B5: .
A6: Valores | B6: CARRETA | C6: COLHEITADEIRA | D6: PLANTADEIRA | E6: PLATAFORMA | F6: PULVERIZADOR | G6: TRATOR
A7: Media Proprio | C7: 1077.7778 | D7: 1122 | E7: 371.42857 | F7: 1056 | G7: 1098.5
A8: Media Terceiro | B8: 300 | C8: 1390 | D8: 2000 | E8: 670 | F8: 9600 | G8: 1122.9
A9: Qtd Proprio | C9: 9 | D9: 1 | E9: 7 | F9: 2 | G9: 36
A10: Qtd Terceiro | B10: 2 | C10: 5 | D10: 1 | E10: 5 | F10: 1 | G10: 17
A11: G01 | B11: CARRETA | C11: COLHEITADEIRA | D11: PLANTADEIRA | E11: PLATAFORMA | F11: PULVERIZADOR | G11: TRATOR
A12: Meta Frete 2026 | C12: 2200 | D12: 1850 | E12: 800 | F12: 2000 | G12: 1500
A13: Média (P+T) | B13: =IFERROR((B7*B9 + B8*B10) / (B9 + B10), "") -> 300 | C13: =IFERROR((C7*C9 + C8*C10) / (C9 + C10), "") -> 1189.2857 | D13: =IFERROR((D7*D9 + D8*D10) / (D9 + D10), "") -> 1561 | E13: =IFERROR((E7*E9 + E8*E10) / (E9 + E10), "") -> 495.83333 | F13: =IFERROR((F7*F9 + F8*F10) / (F9 + F10), "") -> 3904 | G13: =IFERROR((G7*G9 + G8*G10) / (G9 + G10), "") -> 1106.3264
A15: PREV | B15: (Tudo) | C15: G02
A17: Rótulos de Linha | B17: Soma Proprio | C17: Soma Terceiro | D17: Qtd Frete
A18: TRATOR | B18: 39546 | C18: 19089.3 | D18: 55
A19: PULVERIZADOR | B19: 2112 | C19: 9600 | D19: 3
A20: COLHEITADEIRA | B20: 9700 | C20: 6950 | D20: 15
A21: PLATAFORMA | B21: 2600 | C21: 3350 | D21: 12
A22: PLANTADEIRA | B22: 1122 | C22: 2000 | D22: 2
A23: CARRETA | C23: 600 | D23: 2
C26: G03
A28: TERCEIRO | B28: Valor Total | C28: Total KM
A29: TERCEIRO MAZETTO | B29: 12051.3 | C29: 1914
A30: TERCEIRO COLOMBO | B30: 9600 | C30: 733
A31: TERCEIRO AGROMAQ | B31: 7200 | C31: 1374
A32: TERCEIRO ZORTEA | B32: 5400 | C32: 956
A33: TERCEIRO DEMETRIO | B33: 2830 | C33: 748
A34: TERCEIRO NELSON | B34: 2270 | C34: 315
A35: TERCEIRO JAPONES | B35: 1328 | C35: 166
A36: TERCEIRO STOSKI | B36: 910 | C36: 70
A43: DATA | B43: (Tudo) | D43: DATA | E43: (Tudo) | G43: DATA | H43: (Tudo)
A44: TIPO | B44: Munck | D44: TIPO | E44: Frete Peças M | G44: TIPO | H44: Frete Peças T
B45: G04 | E45: G05 | H45: G06
A46: MUNCK | B46: R$ | D46: MOTOBOY | E46: R$ | G46: TRANSPORTADORA | H46: R$
A47: ARAPOTI | B47: 2745 | D47: PG | E47: 9345.62 | G47: PG | H47: 7232
A48: IRATI | B48: 1262 | D48: CASTRO | E48: 4770 | G48: ARAPOTI | H48: 1100
A49: PG | B49: 440 | D49: GRPVA | E49: 1800 | G49: GRPVA | H49: 1100
A50: GRPVA | B50: 270 | D50: TIBAGI | E50: 1760 | G50: CASTRO | H50: 850
A51: Total Geral | B51: 4717 | D51: PRUDE | E51: 1095 | G51: TIBAGI | H51: 830
D52: ARAPOTI | E52: 990 | G52: IRATI | H52: 602
D53: IRATI | E53: 360 | G53: PRUDE | H53: 550
...

Sheet FRETE MÁQUINAS
A1: STATUS | B1: FRETE | C1: HR | D1: KM | E1: R$ PROP | F1: R$ TERC | G1: CHASSI | H1: PREV | I1: REAL | J1: CLIENTE/NOTA | K1: SOLICITANTE | L1: ESTÁ: | M1: VAI: | N1: TIPO | O1: ESTÁ EM: | P1: VAI PARA: | Q1: OBS | R1: FILIAL CUSTOS | S1: EQUIP
A2: CONCLUIDO | B2: TERCEIRO DEMETRIO | C2: =IFERROR((D2*1.5)/1440, "?") -> 0.10208333 | D2: 98 | F2: 300 | G2: 1BM5060ECN4103629 | H2: 45964 | I2: 45964 | J2: MANUTENÇÃO → CLIENTE | K2: daisy.kakol | L2: IRATI | M2: CLIENTE | N2: DE LOJA PARA CLIENTE | O2: MPA | P2: https://maps.app.goo.gl/MLVchYQrLvQGhWWp6 | Q2: cezar | R2: IRATI | S2: TRATOR | T2: =IF( OR( IFERROR(FIND("BM",G2),0)>0, IFERROR(FIND("PY",G2),0)>0 ), MID(TRIM(SUBSTITUTE(SUBSTITUTE(G2,CHAR(160),""),CHAR(9),"")),4,5), MID(TRIM(SUBSTITUTE(SUBSTITUTE(G2,CHAR(160),""),CHAR(9),"")),4,4) ) -> 5060E | U2: {=_xlfn.LET( _xlpm.ch, TRIM(SUBSTITUTE(G2,CHAR(160),"")), _xlpm.ehTrator, OR(IFERROR(FIND("BM",_xlpm.ch),0)>0, IFERROR(FIND("PY",_xlpm.ch),0)>0), _xlpm.chave, IF(_xlpm.ehTrator, MID(_xlpm.ch,4,5), MID(_xlpm.ch,4,4)), _xlpm.fonte, IF(LEN(_xlpm.chave)=5, UTIL!BS:BS, UTIL!BR:BR), _xlpm.modelo, TRIM(SUBSTITUTE(T2,CHAR(160),"")), _xlpm.nomeMod, IFERROR(_xlfn.XLOOKUP("*"&_xlpm.modelo&"*", UTIL!D:D, UTIL!B:B, "", 2), IFERROR(_xlfn.XLOOKUP("*"&_xlpm.modelo&"*", UTIL!E:E, UTIL!B:B, "", 2), "")), _xlpm.tipoMod, IF(_xlpm.nomeMod="", "", IFERROR(LEFT(_xlpm.nomeMod, FIND(" ", _xlpm.nomeMod)-1), _xlpm.nomeMod)), _xlpm.dimMod, IFERROR(_xlfn.XLOOKUP("*"&_xlpm.modelo&"*", UTIL!D:D, UTIL!K:K, "", 2), IFERROR(_xlfn.XLOOKUP("*"&_xlpm.modelo&"*", UTIL!E:E, UTIL!K:K, "", 2), "")), _xlpm.tipotxt_antigo, IF(_xlpm.ehTrator, "TRATOR", IFERROR(_xlfn.XLOOKUP(_xlpm.chave, _xlpm.fonte, UTIL!BP:BP, "", 0), IFERROR(_xlfn.XLOOKUP("*"&_xlpm.chave&"*", _xlpm.fonte, UTIL!BP:BP, "", 2), "Não encontrado"))), _xlpm.dimtxt_antigo, IFERROR(_xlfn.XLOOKUP(_xlpm.chave, _xlpm.fonte, UTIL!BY:BY, "", 0), IFERROR(_xlfn.XLOOKUP("*"&_xlpm.chave&"*", _xlpm.fonte, UTIL!BY:BY, "", 2), "Não encontrado")), _xlpm.tipotxt, IF(_xlpm.tipoMod<>"", _xlpm.tipoMod, _xlpm.tipotxt_antigo), _xlpm.dimtxt, IF(_xlpm.dimMod<>"", _xlpm.dimMod, _xlpm.dimtxt_antigo), _xlpm.deTxt, IF(L2="CLIENTE", O2, IF(LEFT(L2,4)="http", L2, "MACPONTA AGRO DE "&L2)), _xlpm.paraBase, IF(M2="CLIENTE", P2, M2), _xlpm.paraTxt, IF(LEFT(_xlpm.paraBase,4)="http", _xlpm.paraBase, "MACPONTA AGRO DE "&_xlpm.paraBase), _xlpm.nfParte, IF(LEN(TRIM(I2))=0, "", " -NF "&TRIM(I2)), "- " & _xlpm.tipotxt & ": *" & G2 & "*" & CHAR(13)&CHAR(10) & "- " & _xlpm.dimtxt & CHAR(13)&CHAR(10) & "- *Cliente*: " & J2 & _xlpm.nfParte & CHAR(13)&CHAR(10) & "- *Obs:* " & Q2 & CHAR(13)&CHAR(10) & CHAR(10) & "- *De*: " & _xlpm.deTxt & CHAR(13)&CHAR(10) & "- *Para*: " & _xlpm.paraTxt & CHAR(13)&CHAR(10) & "- *Ida e volta*: +/- " & TEXT(((D2*1.5)/1440),"h:mm") & "h | " & D2 & "km" )} -> - TRATOR: *1BM5060ECN4103629*_x000D_ - _x000D_ - *Cliente*: MANUTENÇÃO → CLIENTE -NF 45964_x000D_ - *Obs:* cezar_x000D_ - *De*: MACPONTA AGRO DE IRATI_x000D_ - *Para*: https://maps.app.goo.gl/MLVchYQrLvQGhWWp6_x000D_ - *Ida e volta*: +/- 2:27h | 98km
A3: CONCLUIDO | B3: TERCEIRO DEMETRIO | C3: =IFERROR((D3*1.5)/1440, "?") -> 0.11979167 | D3: 115 | F3: 500 | G3: 1BM5080ECP4111950 | H3: 45964 | I3: 45964 | J3: MANUTENÇÃO → CLIENTE | K3: daisy.kakol | L3: IRATI | M3: CLIENTE | N3: DE LOJA PARA CLIENTE | O3: MPA | P3: https://maps.app.goo.gl/rYQLkSMERduCoffL8 | Q3: RICARDO DRANKA | R3: IRATI | S3: TRATOR | T3: =IF( OR( IFERROR(FIND("BM",G3),0)>0, IFERROR(FIND("PY",G3),0)>0 ), MID(TRIM(SUBSTITUTE(SUBSTITUTE(G3,CHAR(160),""),CHAR(9),"")),4,5), MID(TRIM(SUBSTITUTE(SUBSTITUTE(G3,CHAR(160),""),CHAR(9),"")),4,4) ) -> 5080E | U3: {=_xlfn.LET( _xlpm.ch, TRIM(SUBSTITUTE(G3,CHAR(160),"")), _xlpm.ehTrator, OR(IFERROR(FIND("BM",_xlpm.ch),0)>0, IFERROR(FIND("PY",_xlpm.ch),0)>0), _xlpm.chave, IF(_xlpm.ehTrator, MID(_xlpm.ch,4,5), MID(_xlpm.ch,4,4)), _xlpm.fonte, IF(LEN(_xlpm.chave)=5, UTIL!BS:BS, UTIL!BR:BR), _xlpm.modelo, TRIM(SUBSTITUTE(T3,CHAR(160),"")), _xlpm.nomeMod, IFERROR(_xlfn.XLOOKUP("*"&_xlpm.modelo&"*", UTIL!D:D, UTIL!B:B, "", 2), IFERROR(_xlfn.XLOOKUP("*"&_xlpm.modelo&"*", UTIL!E:E, UTIL!B:B, "", 2), "")), _xlpm.tipoMod, IF(_xlpm.nomeMod="", "", IFERROR(LEFT(_xlpm.nomeMod, FIND(" ", _xlpm.nomeMod)-1), _xlpm.nomeMod)), _xlpm.dimMod, IFERROR(_xlfn.XLOOKUP("*"&_xlpm.modelo&"*", UTIL!D:D, UTIL!K:K, "", 2), IFERROR(_xlfn.XLOOKUP("*"&_xlpm.modelo&"*", UTIL!E:E, UTIL!K:K, "", 2), "")), _xlpm.tipotxt_antigo, IF(_xlpm.ehTrator, "TRATOR", IFERROR(_xlfn.XLOOKUP(_xlpm.chave, _xlpm.fonte, UTIL!BP:BP, "", 0), IFERROR(_xlfn.XLOOKUP("*"&_xlpm.chave&"*", _xlpm.fonte, UTIL!BP:BP, "", 2), "Não encontrado"))), _xlpm.dimtxt_antigo, IFERROR(_xlfn.XLOOKUP(_xlpm.chave, _xlpm.fonte, UTIL!BY:BY, "", 0), IFERROR(_xlfn.XLOOKUP("*"&_xlpm.chave&"*", _xlpm.fonte, UTIL!BY:BY, "", 2), "Não encontrado")), _xlpm.tipotxt, IF(_xlpm.tipoMod<>"", _xlpm.tipoMod, _xlpm.tipotxt_antigo), _xlpm.dimtxt, IF(_xlpm.dimMod<>"", _xlpm.dimMod, _xlpm.dimtxt_antigo), _xlpm.deTxt, IF(L3="CLIENTE", O3, IF(LEFT(L3,4)="http", L3, "MACPONTA AGRO DE "&L3)), _xlpm.paraBase, IF(M3="CLIENTE", P3, M3), _xlpm.paraTxt, IF(LEFT(_xlpm.paraBase,4)="http", _xlpm.paraBase, "MACPONTA AGRO DE "&_xlpm.paraBase), _xlpm.nfParte, IF(LEN(TRIM(I3))=0, "", " -NF "&TRIM(I3)), "- " & _xlpm.tipotxt & ": *" & G3 & "*" & CHAR(13)&CHAR(10) & "- " & _xlpm.dimtxt & CHAR(13)&CHAR(10) & "- *Cliente*: " & J3 & _xlpm.nfParte & CHAR(13)&CHAR(10) & "- *Obs:* " & Q3 & CHAR(13)&CHAR(10) & CHAR(10) & "- *De*: " & _xlpm.deTxt & CHAR(13)&CHAR(10) & "- *Para*: " & _xlpm.paraTxt & CHAR(13)&CHAR(10) & "- *Ida e volta*: +/- " & TEXT(((D3*1.5)/1440),"h:mm") & "h | " & D3 & "km" )} -> - TRATOR: *1BM5080ECP4111950*_x000D_ - _x000D_ - *Cliente*: MANUTENÇÃO → CLIENTE -NF 45964_x000D_ - *Obs:* RICARDO DRANKA_x000D_ - *De*: MACPONTA AGRO DE IRATI_x000D_ - *Para*: https://maps.app.goo.gl/rYQLkSMERduCoffL8_x000D_ - *Ida e volta*: +/- 2:52h | 115km
A4: CONCLUIDO | B4: TERCEIRO DEMETRIO | C4: =IFERROR((D4*1.5)/1440, "?") -> 0.11979167 | D4: 115 | F4: 300 | G4: 1BM5080EEP4112594 | H4: 45964 | I4: 45964 | J4: CLIENTE → MANUTENÇÃO | K4: daisy.kakol | L4: CLIENTE | M4: IRATI | N4: DE CLIENTE PARA LOJA | O4: https://maps.app.goo.gl/MTXwpjxVEM4SBPA46 | P4: MPA | Q4: jose | R4: IRATI | S4: TRATOR | T4: =IF( OR( IFERROR(FIND("BM",G4),0)>0, IFERROR(FIND("PY",G4),0)>0 ), MID(TRIM(SUBSTITUTE(SUBSTITUTE(G4,CHAR(160),""),CHAR(9),"")),4,5), MID(TRIM(SUBSTITUTE(SUBSTITUTE(G4,CHAR(160),""),CHAR(9),"")),4,4) ) -> 5080E | U4: {=_xlfn.LET( _xlpm.ch, TRIM(SUBSTITUTE(G4,CHAR(160),"")), _xlpm.ehTrator, OR(IFERROR(FIND("BM",_xlpm.ch),0)>0, IFERROR(FIND("PY",_xlpm.ch),0)>0), _xlpm.chave, IF(_xlpm.ehTrator, MID(_xlpm.ch,4,5), MID(_xlpm.ch,4,4)), _xlpm.fonte, IF(LEN(_xlpm.chave)=5, UTIL!BS:BS, UTIL!BR:BR), _xlpm.modelo, TRIM(SUBSTITUTE(T4,CHAR(160),"")), _xlpm.nomeMod, IFERROR(_xlfn.XLOOKUP("*"&_xlpm.modelo&"*", UTIL!D:D, UTIL!B:B, "", 2), IFERROR(_xlfn.XLOOKUP("*"&_xlpm.modelo&"*", UTIL!E:E, UTIL!B:B, "", 2), "")), _xlpm.tipoMod, IF(_xlpm.nomeMod="", "", IFERROR(LEFT(_xlpm.nomeMod, FIND(" ", _xlpm.nomeMod)-1), _xlpm.nomeMod)), _xlpm.dimMod, IFERROR(_xlfn.XLOOKUP("*"&_xlpm.modelo&"*", UTIL!D:D, UTIL!K:K, "", 2), IFERROR(_xlfn.XLOOKUP("*"&_xlpm.modelo&"*", UTIL!E:E, UTIL!K:K, "", 2), "")), _xlpm.tipotxt_antigo, IF(_xlpm.ehTrator, "TRATOR", IFERROR(_xlfn.XLOOKUP(_xlpm.chave, _xlpm.fonte, UTIL!BP:BP, "", 0), IFERROR(_xlfn.XLOOKUP("*"&_xlpm.chave&"*", _xlpm.fonte, UTIL!BP:BP, "", 2), "Não encontrado"))), _xlpm.dimtxt_antigo, IFERROR(_xlfn.XLOOKUP(_xlpm.chave, _xlpm.fonte, UTIL!BY:BY, "", 0), IFERROR(_xlfn.XLOOKUP("*"&_xlpm.chave&"*", _xlpm.fonte, UTIL!BY:BY, "", 2), "Não encontrado")), _xlpm.tipotxt, IF(_xlpm.tipoMod<>"", _xlpm.tipoMod, _xlpm.tipotxt_antigo), _xlpm.dimtxt, IF(_xlpm.dimMod<>"", _xlpm.dimMod, _xlpm.dimtxt_antigo), _xlpm.deTxt, IF(L4="CLIENTE", O4, IF(LEFT(L4,4)="http", L4, "MACPONTA AGRO DE "&L4)), _xlpm.paraBase, IF(M4="CLIENTE", P4, M4), _xlpm.paraTxt, IF(LEFT(_xlpm.paraBase,4)="http", _xlpm.paraBase, "MACPONTA AGRO DE "&_xlpm.paraBase), _xlpm.nfParte, IF(LEN(TRIM(I4))=0, "", " -NF "&TRIM(I4)), "- " & _xlpm.tipotxt & ": *" & G4 & "*" & CHAR(13)&CHAR(10) & "- " & _xlpm.dimtxt & CHAR(13)&CHAR(10) & "- *Cliente*: " & J4 & _xlpm.nfParte & CHAR(13)&CHAR(10) & "- *Obs:* " & Q4 & CHAR(13)&CHAR(10) & CHAR(10) & "- *De*: " & _xlpm.deTxt & CHAR(13)&CHAR(10) & "- *Para*: " & _xlpm.paraTxt & CHAR(13)&CHAR(10) & "- *Ida e volta*: +/- " & TEXT(((D4*1.5)/1440),"h:mm") & "h | " & D4 & "km" )} -> - TRATOR: *1BM5080EEP4112594*_x000D_ - _x000D_ - *Cliente*: CLIENTE → MANUTENÇÃO -NF 45964_x000D_ - *Obs:* jose_x000D_ - *De*: https://maps.app.goo.gl/MTXwpjxVEM4SBPA46_x000D_ - *Para*: MACPONTA AGRO DE IRATI_x000D_ - *Ida e volta*: +/- 2:52h | 115km
A5: CONCLUIDO | B5: TERCEIRO MAZETTO | C5: =IFERROR((D5*1.5)/1440, "?") -> 0.15625 | D5: 150 | F5: 1352 | G5: 1BM5080EPS4204124 | H5: 45964 | I5: 45964 | J5: LUIZ HENRIQUE GREIN -NF107347 | K5: euclides.junior | L5: GUARAPUAVA | M5: CLIENTE | N5: DE LOJA PARA CLIENTE | O5: MPA | P5: https://maps.app.goo.gl/jZEWqzLvNcpTnRBE8 | Q5: Emerson | R5: GUARAPUAVA | S5: TRATOR | T5: =IF( OR( IFERROR(FIND("BM",G5),0)>0, IFERROR(FIND("PY",G5),0)>0 ), MID(TRIM(SUBSTITUTE(SUBSTITUTE(G5,CHAR(160),""),CHAR(9),"")),4,5), MID(TRIM(SUBSTITUTE(SUBSTITUTE(G5,CHAR(160),""),CHAR(9),"")),4,4) ) -> 5080E | U5: {=_xlfn.LET( _xlpm.ch, TRIM(SUBSTITUTE(G5,CHAR(160),"")), _xlpm.ehTrator, OR(IFERROR(FIND("BM",_xlpm.ch),0)>0, IFERROR(FIND("PY",_xlpm.ch),0)>0), _xlpm.chave, IF(_xlpm.ehTrator, MID(_xlpm.ch,4,5), MID(_xlpm.ch,4,4)), _xlpm.fonte, IF(LEN(_xlpm.chave)=5, UTIL!BS:BS, UTIL!BR:BR), _xlpm.modelo, TRIM(SUBSTITUTE(T5,CHAR(160),"")), _xlpm.nomeMod, IFERROR(_xlfn.XLOOKUP("*"&_xlpm.modelo&"*", UTIL!D:D, UTIL!B:B, "", 2), IFERROR(_xlfn.XLOOKUP("*"&_xlpm.modelo&"*", UTIL!E:E, UTIL!B:B, "", 2), "")), _xlpm.tipoMod, IF(_xlpm.nomeMod="", "", IFERROR(LEFT(_xlpm.nomeMod, FIND(" ", _xlpm.nomeMod)-1), _xlpm.nomeMod)), _xlpm.dimMod, IFERROR(_xlfn.XLOOKUP("*"&_xlpm.modelo&"*", UTIL!D:D, UTIL!K:K, "", 2), IFERROR(_xlfn.XLOOKUP("*"&_xlpm.modelo&"*", UTIL!E:E, UTIL!K:K, "", 2), "")), _xlpm.tipotxt_antigo, IF(_xlpm.ehTrator, "TRATOR", IFERROR(_xlfn.XLOOKUP(_xlpm.chave, _xlpm.fonte, UTIL!BP:BP, "", 0), IFERROR(_xlfn.XLOOKUP("*"&_xlpm.chave&"*", _xlpm.fonte, UTIL!BP:BP, "", 2), "Não encontrado"))), _xlpm.dimtxt_antigo, IFERROR(_xlfn.XLOOKUP(_xlpm.chave, _xlpm.fonte, UTIL!BY:BY, "", 0), IFERROR(_xlfn.XLOOKUP("*"&_xlpm.chave&"*", _xlpm.fonte, UTIL!BY:BY, "", 2), "Não encontrado")), _xlpm.tipotxt, IF(_xlpm.tipoMod<>"", _xlpm.tipoMod, _xlpm.tipotxt_antigo), _xlpm.dimtxt, IF(_xlpm.dimMod<>"", _xlpm.dimMod, _xlpm.dimtxt_antigo), _xlpm.deTxt, IF(L5="CLIENTE", O5, IF(LEFT(L5,4)="http", L5, "MACPONTA AGRO DE "&L5)), _xlpm.paraBase, IF(M5="CLIENTE", P5, M5), _xlpm.paraTxt, IF(LEFT(_xlpm.paraBase,4)="http", _xlpm.paraBase, "MACPONTA AGRO DE "&_xlpm.paraBase), _xlpm.nfParte, IF(LEN(TRIM(I5))=0, "", " -NF "&TRIM(I5)), "- " & _xlpm.tipotxt & ": *" & G5 & "*" & CHAR(13)&CHAR(10) & "- " & _xlpm.dimtxt & CHAR(13)&CHAR(10) & "- *Cliente*: " & J5 & _xlpm.nfParte & CHAR(13)&CHAR(10) & "- *Obs:* " & Q5 & CHAR(13)&CHAR(10) & CHAR(10) & "- *De*: " & _xlpm.deTxt & CHAR(13)&CHAR(10) & "- *Para*: " & _xlpm.paraTxt & CHAR(13)&CHAR(10) & "- *Ida e volta*: +/- " & TEXT(((D5*1.5)/1440),"h:mm") & "h | " & D5 & "km" )} -> - TRATOR: *1BM5080EPS4204124*_x000D_ - _x000D_ - *Cliente*: LUIZ HENRIQUE GREIN -NF107347 -NF 45964_x000D_ - *Obs:* Emerson_x000D_ - *De*: MACPONTA AGRO DE GUARAPUAVA_x000D_ - *Para*: https://maps.app.goo.gl/jZEWqzLvNcpTnRBE8_x000D_ - *Ida e volta*: +/- 3:45h | 150km
A6: CONCLUIDO | B6: TERCEIRO MAZETTO | C6: =IFERROR((D6*1.5)/1440, "?") -> 0.17916667 | D6: 172 | F6: 650 | G6: 1CQFA30AAS0160114 | H6: 45964 | I6: 45964 | J6: ARNALDO STOCK -NF107847 | K6: euclides.junior | L6: GUARAPUAVA | M6: CLIENTE | N6: DE LOJA PARA CLIENTE | O6: MPA | P6: https://maps.app.goo.gl/kFwUPivsMpYS8pGd8 | Q6: Fabio | R6: GUARAPUAVA | S6: PLATAFORMA | T6: =IF( OR( IFERROR(FIND("BM",G6),0)>0, IFERROR(FIND("PY",G6),0)>0 ), MID(TRIM(SUBSTITUTE(SUBSTITUTE(G6,CHAR(160),""),CHAR(9),"")),4,5), MID(TRIM(SUBSTITUTE(SUBSTITUTE(G6,CHAR(160),""),CHAR(9),"")),4,4) ) -> FA30 | U6: {=_xlfn.LET( _xlpm.ch, TRIM(SUBSTITUTE(G6,CHAR(160),"")), _xlpm.ehTrator, OR(IFERROR(FIND("BM",_xlpm.ch),0)>0, IFERROR(FIND("PY",_xlpm.ch),0)>0), _xlpm.chave, IF(_xlpm.ehTrator, MID(_xlpm.ch,4,5), MID(_xlpm.ch,4,4)), _xlpm.fonte, IF(LEN(_xlpm.chave)=5, UTIL!BS:BS, UTIL!BR:BR), _xlpm.modelo, TRIM(SUBSTITUTE(T6,CHAR(160),"")), _xlpm.nomeMod, IFERROR(_xlfn.XLOOKUP("*"&_xlpm.modelo&"*", UTIL!D:D, UTIL!B:B, "", 2), IFERROR(_xlfn.XLOOKUP("*"&_xlpm.modelo&"*", UTIL!E:E, UTIL!B:B, "", 2), "")), _xlpm.tipoMod, IF(_xlpm.nomeMod="", "", IFERROR(LEFT(_xlpm.nomeMod, FIND(" ", _xlpm.nomeMod)-1), _xlpm.nomeMod)), _xlpm.dimMod, IFERROR(_xlfn.XLOOKUP("*"&_xlpm.modelo&"*", UTIL!D:D, UTIL!K:K, "", 2), IFERROR(_xlfn.XLOOKUP("*"&_xlpm.modelo&"*", UTIL!E:E, UTIL!K:K, "", 2), "")), _xlpm.tipotxt_antigo, IF(_xlpm.ehTrator, "TRATOR", IFERROR(_xlfn.XLOOKUP(_xlpm.chave, _xlpm.fonte, UTIL!BP:BP, "", 0), IFERROR(_xlfn.XLOOKUP("*"&_xlpm.chave&"*", _xlpm.fonte, UTIL!BP:BP, "", 2), "Não encontrado"))), _xlpm.dimtxt_antigo, IFERROR(_xlfn.XLOOKUP(_xlpm.chave, _xlpm.fonte, UTIL!BY:BY, "", 0), IFERROR(_xlfn.XLOOKUP("*"&_xlpm.chave&"*", _xlpm.fonte, UTIL!BY:BY, "", 2), "Não encontrado")), _xlpm.tipotxt, IF(_xlpm.tipoMod<>"", _xlpm.tipoMod, _xlpm.tipotxt_antigo), _xlpm.dimtxt, IF(_xlpm.dimMod<>"", _xlpm.dimMod, _xlpm.dimtxt_antigo), _xlpm.deTxt, IF(L6="CLIENTE", O6, IF(LEFT(L6,4)="http", L6, "MACPONTA AGRO DE "&L6)), _xlpm.paraBase, IF(M6="CLIENTE", P6, M6), _xlpm.paraTxt, IF(LEFT(_xlpm.paraBase,4)="http", _xlpm.paraBase, "MACPONTA AGRO DE "&_xlpm.paraBase), _xlpm.nfParte, IF(LEN(TRIM(I6))=0, "", " -NF "&TRIM(I6)), "- " & _xlpm.tipotxt & ": *" & G6 & "*" & CHAR(13)&CHAR(10) & "- " & _xlpm.dimtxt & CHAR(13)&CHAR(10) & "- *Cliente*: " & J6 & _xlpm.nfParte & CHAR(13)&CHAR(10) & "- *Obs:* " & Q6 & CHAR(13)&CHAR(10) & CHAR(10) & "- *De*: " & _xlpm.deTxt & CHAR(13)&CHAR(10) & "- *Para*: " & _xlpm.paraTxt & CHAR(13)&CHAR(10) & "- *Ida e volta*: +/- " & TEXT(((D6*1.5)/1440),"h:mm") & "h | " & D6 & "km" )} -> - PLATAFORMA: *1CQFA30AAS0160114*_x000D_ - A:1,60 x C:9,14 x L:1,80-1,80 x P:2.900kg_x000D_ - *Cliente*: ARNALDO STOCK -NF107847 -NF 45964_x000D_ - *Obs:* Fabio _x000D_ - *De*: MACPONTA AGRO DE GUARAPUAVA_x000D_ - *Para*: https://maps.app.goo.gl/kFwUPivsMpYS8pGd8_x000D_ - *Ida e volta*: +/- 4:18h | 172km
A7: CONCLUIDO | B7: TERCEIRO MAZETTO | C7: =IFERROR((D7*1.5)/1440, "?") -> 0.17916667 | D7: 172 | F7: 650 | G7: 1CQS760ACS0160134 | H7: 45964 | I7: 45964 | J7: ARNALDO STOCK -NF107847 | K7: euclides.junior | L7: GUARAPUAVA | M7: CLIENTE | N7: DE LOJA PARA CLIENTE | O7: MPA | P7: https://maps.app.goo.gl/Kk5FKYUBPHUbo26P8 | Q7: Fabio | R7: GUARAPUAVA | S7: COLHEITADEIRA | T7: =IF( OR( IFERROR(FIND("BM",G7),0)>0, IFERROR(FIND("PY",G7),0)>0 ), MID(TRIM(SUBSTITUTE(SUBSTITUTE(G7,CHAR(160),""),CHAR(9),"")),4,5), MID(TRIM(SUBSTITUTE(SUBSTITUTE(G7,CHAR(160),""),CHAR(9),"")),4,4) ) -> S760 | U7: {=_xlfn.LET( _xlpm.ch, TRIM(SUBSTITUTE(G7,CHAR(160),"")), _xlpm.ehTrator, OR(IFERROR(FIND("BM",_xlpm.ch),0)>0, IFERROR(FIND("PY",_xlpm.ch),0)>0), _xlpm.chave, IF(_xlpm.ehTrator, MID(_xlpm.ch,4,5), MID(_xlpm.ch,4,4)), _xlpm.fonte, IF(LEN(_xlpm.chave)=5, UTIL!BS:BS, UTIL!BR:BR), _xlpm.modelo, TRIM(SUBSTITUTE(T7,CHAR(160),"")), _xlpm.nomeMod, IFERROR(_xlfn.XLOOKUP("*"&_xlpm.modelo&"*", UTIL!D:D, UTIL!B:B, "", 2), IFERROR(_xlfn.XLOOKUP("*"&_xlpm.modelo&"*", UTIL!E:E, UTIL!B:B, "", 2), "")), _xlpm.tipoMod, IF(_xlpm.nomeMod="", "", IFERROR(LEFT(_xlpm.nomeMod, FIND(" ", _xlpm.nomeMod)-1), _xlpm.nomeMod)), _xlpm.dimMod, IFERROR(_xlfn.XLOOKUP("*"&_xlpm.modelo&"*", UTIL!D:D, UTIL!K:K, "", 2), IFERROR(_xlfn.XLOOKUP("*"&_xlpm.modelo&"*", UTIL!E:E, UTIL!K:K, "", 2), "")), _xlpm.tipotxt_antigo, IF(_xlpm.ehTrator, "TRATOR", IFERROR(_xlfn.XLOOKUP(_xlpm.chave, _xlpm.fonte, UTIL!BP:BP, "", 0), IFERROR(_xlfn.XLOOKUP("*"&_xlpm.chave&"*", _xlpm.fonte, UTIL!BP:BP, "", 2), "Não encontrado"))), _xlpm.dimtxt_antigo, IFERROR(_xlfn.XLOOKUP(_xlpm.chave, _xlpm.fonte, UTIL!BY:BY, "", 0), IFERROR(_xlfn.XLOOKUP("*"&_xlpm.chave&"*", _xlpm.fonte, UTIL!BY:BY, "", 2), "Não encontrado")), _xlpm.tipotxt, IF(_xlpm.tipoMod<>"", _xlpm.tipoMod, _xlpm.tipotxt_antigo), _xlpm.dimtxt, IF(_xlpm.dimMod<>"", _xlpm.dimMod, _xlpm.dimtxt_antigo), _xlpm.deTxt, IF(L7="CLIENTE", O7, IF(LEFT(L7,4)="http", L7, "MACPONTA AGRO DE "&L7)), _xlpm.paraBase, IF(M7="CLIENTE", P7, M7), _xlpm.paraTxt, IF(LEFT(_xlpm.paraBase,4)="http", _xlpm.paraBase, "MACPONTA AGRO DE "&_xlpm.paraBase), _xlpm.nfParte, IF(LEN(TRIM(I7))=0, "", " -NF "&TRIM(I7)), "- " & _xlpm.tipotxt & ": *" & G7 & "*" & CHAR(13)&CHAR(10) & "- " & _xlpm.dimtxt & CHAR(13)&CHAR(10) & "- *Cliente*: " & J7 & _xlpm.nfParte & CHAR(13)&CHAR(10) & "- *Obs:* " & Q7 & CHAR(13)&CHAR(10) & CHAR(10) & "- *De*: " & _xlpm.deTxt & CHAR(13)&CHAR(10) & "- *Para*: " & _xlpm.paraTxt & CHAR(13)&CHAR(10) & "- *Ida e volta*: +/- " & TEXT(((D7*1.5)/1440),"h:mm") & "h | " & D7 & "km" )} -> - COLHEITADEIRA: *1CQS760ACS0160134*_x000D_ - A:4,00 x C:10,60 x L:3,50-5,20 x P:18.599kg_x000D_ - *Cliente*: ARNALDO STOCK -NF107847 -NF 45964_x000D_ - *Obs:* Fabio _x000D_ - *De*: MACPONTA AGRO DE GUARAPUAVA_x000D_ - *Para*: https://maps.app.goo.gl/Kk5FKYUBPHUbo26P8_x000D_ - *Ida e volta*: +/- 4:18h | 172km
A8: CONCLUIDO | B8: TERCEIRO STOSKI | C8: =IFERROR((D8*1.5)/1440, "?") -> 0.072916667 | D8: 70 | F8: 910 | G8: 1BM6135MPSH000596 | H8: 45964 | I8: 45964 | J8: LAURO MIGUEL STRONA -NF76755 | K8: marcio.jacovossi | L8: IRATI | M8: CLIENTE | N8: DE LOJA PARA CLIENTE | O8: MPA | P8: https://maps.app.goo.gl/JxzGitfYRrvxzYUL9 | Q8: LAURO MIGUEL STRONA 42 999269190 | R8: IRATI | S8: TRATOR | T8: =IF( OR( IFERROR(FIND("BM",G8),0)>0, IFERROR(FIND("PY",G8),0)>0 ), MID(TRIM(SUBSTITUTE(SUBSTITUTE(G8,CHAR(160),""),CHAR(9),"")),4,5), MID(TRIM(SUBSTITUTE(SUBSTITUTE(G8,CHAR(160),""),CHAR(9),"")),4,4) ) -> 6135M | U8: {=_xlfn.LET( _xlpm.ch, TRIM(SUBSTITUTE(G8,CHAR(160),"")), _xlpm.ehTrator, OR(IFERROR(FIND("BM",_xlpm.ch),0)>0, IFERROR(FIND("PY",_xlpm.ch),0)>0), _xlpm.chave, IF(_xlpm.ehTrator, MID(_xlpm.ch,4,5), MID(_xlpm.ch,4,4)), _xlpm.fonte, IF(LEN(_xlpm.chave)=5, UTIL!BS:BS, UTIL!BR:BR), _xlpm.modelo, TRIM(SUBSTITUTE(T8,CHAR(160),"")), _xlpm.nomeMod, IFERROR(_xlfn.XLOOKUP("*"&_xlpm.modelo&"*", UTIL!D:D, UTIL!B:B, "", 2), IFERROR(_xlfn.XLOOKUP("*"&_xlpm.modelo&"*", UTIL!E:E, UTIL!B:B, "", 2), "")), _xlpm.tipoMod, IF(_xlpm.nomeMod="", "", IFERROR(LEFT(_xlpm.nomeMod, FIND(" ", _xlpm.nomeMod)-1), _xlpm.nomeMod)), _xlpm.dimMod, IFERROR(_xlfn.XLOOKUP("*"&_xlpm.modelo&"*", UTIL!D:D, UTIL!K:K, "", 2), IFERROR(_xlfn.XLOOKUP("*"&_xlpm.modelo&"*", UTIL!E:E, UTIL!K:K, "", 2), "")), _xlpm.tipotxt_antigo, IF(_xlpm.ehTrator, "TRATOR", IFERROR(_xlfn.XLOOKUP(_xlpm.chave, _xlpm.fonte, UTIL!BP:BP, "", 0), IFERROR(_xlfn.XLOOKUP("*"&_xlpm.chave&"*", _xlpm.fonte, UTIL!BP:BP, "", 2), "Não encontrado"))), _xlpm.dimtxt_antigo, IFERROR(_xlfn.XLOOKUP(_xlpm.chave, _xlpm.fonte, UTIL!BY:BY, "", 0), IFERROR(_xlfn.XLOOKUP("*"&_xlpm.chave&"*", _xlpm.fonte, UTIL!BY:BY, "", 2), "Não encontrado")), _xlpm.tipotxt, IF(_xlpm.tipoMod<>"", _xlpm.tipoMod, _xlpm.tipotxt_antigo), _xlpm.dimtxt, IF(_xlpm.dimMod<>"", _xlpm.dimMod, _xlpm.dimtxt_antigo), _xlpm.deTxt, IF(L8="CLIENTE", O8, IF(LEFT(L8,4)="http", L8, "MACPONTA AGRO DE "&L8)), _xlpm.paraBase, IF(M8="CLIENTE", P8, M8), _xlpm.paraTxt, IF(LEFT(_xlpm.paraBase,4)="http", _xlpm.paraBase, "MACPONTA AGRO DE "&_xlpm.paraBase), _xlpm.nfParte, IF(LEN(TRIM(I8))=0, "", " -NF "&TRIM(I8)), "- " & _xlpm.tipotxt & ": *" & G8 & "*" & CHAR(13)&CHAR(10) & "- " & _xlpm.dimtxt & CHAR(13)&CHAR(10) & "- *Cliente*: " & J8 & _xlpm.nfParte & CHAR(13)&CHAR(10) & "- *Obs:* " & Q8 & CHAR(13)&CHAR(10) & CHAR(10) & "- *De*: " & _xlpm.deTxt & CHAR(13)&CHAR(10) & "- *Para*: " & _xlpm.paraTxt & CHAR(13)&CHAR(10) & "- *Ida e volta*: +/- " & TEXT(((D8*1.5)/1440),"h:mm") & "h | " & D8 & "km" )} -> - TRATOR: *1BM6135MPSH000596*_x000D_ - _x000D_ - *Cliente*: LAURO MIGUEL STRONA -NF76755 -NF 45964_x000D_ - *Obs:* LAURO MIGUEL STRONA 42 999269190_x000D_ - *De*: MACPONTA AGRO DE IRATI_x000D_ - *Para*: https://maps.app.goo.gl/JxzGitfYRrvxzYUL9_x000D_ - *Ida e volta*: +/- 1:45h | 70km
A9: CONCLUIDO | B9: PROPRIO VW | C9: =IFERROR((D9*1.5)/1440, "?") -> 0.34375 | D9: 330 | E9: =IFERROR((D9*6),"?") -> 1980 | G9: 1NW4025MVKF190132 | H9: 45965 | I9: 45965 | J9: MARLON BONILHA -NF61707 | K9: edenilson.mattos | L9: PONTA GROSSA | M9: CLIENTE | N9: DE LOJA PARA CLIENTE | O9: MPA | P9: https://maps.app.goo.gl/F6zwbnVFirHNNuCLA | Q9: Contato CEN Alison 43.98409-2094 | R9: PONTA GROSSA | S9: PULVERIZADOR | T9: =IF( OR( IFERROR(FIND("BM",G9),0)>0, IFERROR(FIND("PY",G9),0)>0 ), MID(TRIM(SUBSTITUTE(SUBSTITUTE(G9,CHAR(160),""),CHAR(9),"")),4,5), MID(TRIM(SUBSTITUTE(SUBSTITUTE(G9,CHAR(160),""),CHAR(9),"")),4,4) ) -> 4025 | U9: {=_xlfn.LET( _xlpm.ch, TRIM(SUBSTITUTE(G9,CHAR(160),"")), _xlpm.ehTrator, OR(IFERROR(FIND("BM",_xlpm.ch),0)>0, IFERROR(FIND("PY",_xlpm.ch),0)>0), _xlpm.chave, IF(_xlpm.ehTrator, MID(_xlpm.ch,4,5), MID(_xlpm.ch,4,4)), _xlpm.fonte, IF(LEN(_xlpm.chave)=5, UTIL!BS:BS, UTIL!BR:BR), _xlpm.modelo, TRIM(SUBSTITUTE(T9,CHAR(160),"")), _xlpm.nomeMod, IFERROR(_xlfn.XLOOKUP("*"&_xlpm.modelo&"*", UTIL!D:D, UTIL!B:B, "", 2), IFERROR(_xlfn.XLOOKUP("*"&_xlpm.modelo&"*", UTIL!E:E, UTIL!B:B, "", 2), "")), _xlpm.tipoMod, IF(_xlpm.nomeMod="", "", IFERROR(LEFT(_xlpm.nomeMod, FIND(" ", _xlpm.nomeMod)-1), _xlpm.nomeMod)), _xlpm.dimMod, IFERROR(_xlfn.XLOOKUP("*"&_xlpm.modelo&"*", UTIL!D:D, UTIL!K:K, "", 2), IFERROR(_xlfn.XLOOKUP("*"&_xlpm.modelo&"*", UTIL!E:E, UTIL!K:K, "", 2), "")), _xlpm.tipotxt_antigo, IF(_xlpm.ehTrator, "TRATOR", IFERROR(_xlfn.XLOOKUP(_xlpm.chave, _xlpm.fonte, UTIL!BP:BP, "", 0), IFERROR(_xlfn.XLOOKUP("*"&_xlpm.chave&"*", _xlpm.fonte, UTIL!BP:BP, "", 2), "Não encontrado"))), _xlpm.dimtxt_antigo, IFERROR(_xlfn.XLOOKUP(_xlpm.chave, _xlpm.fonte, UTIL!BY:BY, "", 0), IFERROR(_xlfn.XLOOKUP("*"&_xlpm.chave&"*", _xlpm.fonte, UTIL!BY:BY, "", 2), "Não encontrado")), _xlpm.tipotxt, IF(_xlpm.tipoMod<>"", _xlpm.tipoMod, _xlpm.tipotxt_antigo), _xlpm.dimtxt, IF(_xlpm.dimMod<>"", _xlpm.dimMod, _xlpm.dimtxt_antigo), _xlpm.deTxt, IF(L9="CLIENTE", O9, IF(LEFT(L9,4)="http", L9, "MACPONTA AGRO DE "&L9)), _xlpm.paraBase, IF(M9="CLIENTE", P9, M9), _xlpm.paraTxt, IF(LEFT(_xlpm.paraBase,4)="http", _xlpm.paraBase, "MACPONTA AGRO DE "&_xlpm.paraBase), _xlpm.nfParte, IF(LEN(TRIM(I9))=0, "", " -NF "&TRIM(I9)), "- " & _xlpm.tipotxt & ": *" & G9 & "*" & CHAR(13)&CHAR(10) & "- " & _xlpm.dimtxt & CHAR(13)&CHAR(10) & "- *Cliente*: " & J9 & _xlpm.nfParte & CHAR(13)&CHAR(10) & "- *Obs:* " & Q9 & CHAR(13)&CHAR(10) & CHAR(10) & "- *De*: " & _xlpm.deTxt & CHAR(13)&CHAR(10) & "- *Para*: " & _xlpm.paraTxt & CHAR(13)&CHAR(10) & "- *Ida e volta*: +/- " & TEXT(((D9*1.5)/1440),"h:mm") & "h | " & D9 & "km" )} -> - PULVERIZADOR: *1NW4025MVKF190132*_x000D_ - A:3,34 x C:7,00 x L:2,72-3,30 x P:9.703kg_x000D_ - *Cliente*: MARLON BONILHA -NF61707 -NF 45965_x000D_ - *Obs:* Contato CEN Alison 43.98409-2094_x000D_ - *De*: MACPONTA AGRO DE PONTA GROSSA_x000D_ - *Para*: https://maps.app.goo.gl/F6zwbnVFirHNNuCLA_x000D_ - *Ida e volta*: +/- 8:15h | 330km
A10: CONCLUIDO | B10: PROPRIO VW | C10: =IFERROR((D10*1.5)/1440, "?") -> 0.058333333 | D10: 56 | E10: =IFERROR((D10*6),"?") -> 336 | G10: 1BM5060EES4201594 | H10: 45965 | I10: 45964 | J10: JOAQUIM MASCARENHAS -NF278279 | K10: marcos.ribas | L10: PONTA GROSSA | M10: CLIENTE | N10: DE LOJA PARA CLIENTE | O10: MPA | P10: https://maps.app.goo.gl/s5tPSxgcuWhSkcKc7 | Q10: PAULO - +55 42 9991-2229 - AVISAR ANGELO PARA ACOMPANHAR | R10: PONTA GROSSA | S10: TRATOR | T10: =IF( OR( IFERROR(FIND("BM",G10),0)>0, IFERROR(FIND("PY",G10),0)>0 ), MID(TRIM(SUBSTITUTE(SUBSTITUTE(G10,CHAR(160),""),CHAR(9),"")),4,5), MID(TRIM(SUBSTITUTE(SUBSTITUTE(G10,CHAR(160),""),CHAR(9),"")),4,4) ) -> 5060E | U10: {=_xlfn.LET( _xlpm.ch, TRIM(SUBSTITUTE(G10,CHAR(160),"")), _xlpm.ehTrator, OR(IFERROR(FIND("BM",_xlpm.ch),0)>0, IFERROR(FIND("PY",_xlpm.ch),0)>0), _xlpm.chave, IF(_xlpm.ehTrator, MID(_xlpm.ch,4,5), MID(_xlpm.ch,4,4)), _xlpm.fonte, IF(LEN(_xlpm.chave)=5, UTIL!BS:BS, UTIL!BR:BR), _xlpm.modelo, TRIM(SUBSTITUTE(T10,CHAR(160),"")), _xlpm.nomeMod, IFERROR(_xlfn.XLOOKUP("*"&_xlpm.modelo&"*", UTIL!D:D, UTIL!B:B, "", 2), IFERROR(_xlfn.XLOOKUP("*"&_xlpm.modelo&"*", UTIL!E:E, UTIL!B:B, "", 2), "")), _xlpm.tipoMod, IF(_xlpm.nomeMod="", "", IFERROR(LEFT(_xlpm.nomeMod, FIND(" ", _xlpm.nomeMod)-1), _xlpm.nomeMod)), _xlpm.dimMod, IFERROR(_xlfn.XLOOKUP("*"&_xlpm.modelo&"*", UTIL!D:D, UTIL!K:K, "", 2), IFERROR(_xlfn.XLOOKUP("*"&_xlpm.modelo&"*", UTIL!E:E, UTIL!K:K, "", 2), "")), _xlpm.tipotxt_antigo, IF(_xlpm.ehTrator, "TRATOR", IFERROR(_xlfn.XLOOKUP(_xlpm.chave, _xlpm.fonte, UTIL!BP:BP, "", 0), IFERROR(_xlfn.XLOOKUP("*"&_xlpm.chave&"*", _xlpm.fonte, UTIL!BP:BP, "", 2), "Não encontrado"))), _xlpm.dimtxt_antigo, IFERROR(_xlfn.XLOOKUP(_xlpm.chave, _xlpm.fonte, UTIL!BY:BY, "", 0), IFERROR(_xlfn.XLOOKUP("*"&_xlpm.chave&"*", _xlpm.fonte, UTIL!BY:BY, "", 2), "Não encontrado")), _xlpm.tipotxt, IF(_xlpm.tipoMod<>"", _xlpm.tipoMod, _xlpm.tipotxt_antigo), _xlpm.dimtxt, IF(_xlpm.dimMod<>"", _xlpm.dimMod, _xlpm.dimtxt_antigo), _xlpm.deTxt, IF(L10="CLIENTE", O10, IF(LEFT(L10,4)="http", L10, "MACPONTA AGRO DE "&L10)), _xlpm.paraBase, IF(M10="CLIENTE", P10, M10), _xlpm.paraTxt, IF(LEFT(_xlpm.paraBase,4)="http", _xlpm.paraBase, "MACPONTA AGRO DE "&_xlpm.paraBase), _xlpm.nfParte, IF(LEN(TRIM(I10))=0, "", " -NF "&TRIM(I10)), "- " & _xlpm.tipotxt & ": *" & G10 & "*" & CHAR(13)&CHAR(10) & "- " & _xlpm.dimtxt & CHAR(13)&CHAR(10) & "- *Cliente*: " & J10 & _xlpm.nfParte & CHAR(13)&CHAR(10) & "- *Obs:* " & Q10 & CHAR(13)&CHAR(10) & CHAR(10) & "- *De*: " & _xlpm.deTxt & CHAR(13)&CHAR(10) & "- *Para*: " & _xlpm.paraTxt & CHAR(13)&CHAR(10) & "- *Ida e volta*: +/- " & TEXT(((D10*1.5)/1440),"h:mm") & "h | " & D10 & "km" )} -> - TRATOR: *1BM5060EES4201594*_x000D_ - _x000D_ - *Cliente*: JOAQUIM MASCARENHAS -NF278279 -NF 45964_x000D_ - *Obs:* PAULO - +55 42 9991-2229 - AVISAR ANGELO PARA ACOMPANHAR_x000D_ - *De*: MACPONTA AGRO DE PONTA GROSSA_x000D_ - *Para*: https://maps.app.goo.gl/s5tPSxgcuWhSkcKc7_x000D_ - *Ida e volta*: +/- 1:24h | 56km
A11: CONCLUIDO | B11: TERCEIRO NELSON | C11: =IFERROR((D11*1.5)/1440, "?") -> 0.19270833 | D11: 185 | F11: 1295 | G11: 1BM5060EAP4104558 | H11: 45965 | I11: 45965 | J11: MANUTENÇÃO → CLIENTE | K11: rafael.santos | L11: CLIENTE | M11: ARAPOTI | N11: DE CLIENTE PARA LOJA | O11: https://maps.app.goo.gl/PXTmMqoYPtx48Gex6 | P11: MPA | Q11: LUCIANO DE FREITAS - 43 99624-6946 | R11: ARAPOTI | S11: TRATOR | T11: =IF( OR( IFERROR(FIND("BM",G11),0)>0, IFERROR(FIND("PY",G11),0)>0 ), MID(TRIM(SUBSTITUTE(SUBSTITUTE(G11,CHAR(160),""),CHAR(9),"")),4,5), MID(TRIM(SUBSTITUTE(SUBSTITUTE(G11,CHAR(160),""),CHAR(9),"")),4,4) ) -> 5060E | U11: {=_xlfn.LET( _xlpm.ch, TRIM(SUBSTITUTE(G11,CHAR(160),"")), _xlpm.ehTrator, OR(IFERROR(FIND("BM",_xlpm.ch),0)>0, IFERROR(FIND("PY",_xlpm.ch),0)>0), _xlpm.chave, IF(_xlpm.ehTrator, MID(_xlpm.ch,4,5), MID(_xlpm.ch,4,4)), _xlpm.fonte, IF(LEN(_xlpm.chave)=5, UTIL!BS:BS, UTIL!BR:BR), _xlpm.modelo, TRIM(SUBSTITUTE(T11,CHAR(160),"")), _xlpm.nomeMod, IFERROR(_xlfn.XLOOKUP("*"&_xlpm.modelo&"*", UTIL!D:D, UTIL!B:B, "", 2), IFERROR(_xlfn.XLOOKUP("*"&_xlpm.modelo&"*", UTIL!E:E, UTIL!B:B, "", 2), "")), _xlpm.tipoMod, IF(_xlpm.nomeMod="", "", IFERROR(LEFT(_xlpm.nomeMod, FIND(" ", _xlpm.nomeMod)-1), _xlpm.nomeMod)), _xlpm.dimMod, IFERROR(_xlfn.XLOOKUP("*"&_xlpm.modelo&"*", UTIL!D:D, UTIL!K:K, "", 2), IFERROR(_xlfn.XLOOKUP("*"&_xlpm.modelo&"*", UTIL!E:E, UTIL!K:K, "", 2), "")), _xlpm.tipotxt_antigo, IF(_xlpm.ehTrator, "TRATOR", IFERROR(_xlfn.XLOOKUP(_xlpm.chave, _xlpm.fonte, UTIL!BP:BP, "", 0), IFERROR(_xlfn.XLOOKUP("*"&_xlpm.chave&"*", _xlpm.fonte, UTIL!BP:BP, "", 2), "Não encontrado"))), _xlpm.dimtxt_antigo, IFERROR(_xlfn.XLOOKUP(_xlpm.chave, _xlpm.fonte, UTIL!BY:BY, "", 0), IFERROR(_xlfn.XLOOKUP("*"&_xlpm.chave&"*", _xlpm.fonte, UTIL!BY:BY, "", 2), "Não encontrado")), _xlpm.tipotxt, IF(_xlpm.tipoMod<>"", _xlpm.tipoMod, _xlpm.tipotxt_antigo), _xlpm.dimtxt, IF(_xlpm.dimMod<>"", _xlpm.dimMod, _xlpm.dimtxt_antigo), _xlpm.deTxt, IF(L11="CLIENTE", O11, IF(LEFT(L11,4)="http", L11, "MACPONTA AGRO DE "&L11)), _xlpm.paraBase, IF(M11="CLIENTE", P11, M11), _xlpm.paraTxt, IF(LEFT(_xlpm.paraBase,4)="http", _xlpm.paraBase, "MACPONTA AGRO DE "&_xlpm.paraBase), _xlpm.nfParte, IF(LEN(TRIM(I11))=0, "", " -NF "&TRIM(I11)), "- " & _xlpm.tipotxt & ": *" & G11 & "*" & CHAR(13)&CHAR(10) & "- " & _xlpm.dimtxt & CHAR(13)&CHAR(10) & "- *Cliente*: " & J11 & _xlpm.nfParte & CHAR(13)&CHAR(10) & "- *Obs:* " & Q11 & CHAR(13)&CHAR(10) & CHAR(10) & "- *De*: " & _xlpm.deTxt & CHAR(13)&CHAR(10) & "- *Para*: " & _xlpm.paraTxt & CHAR(13)&CHAR(10) & "- *Ida e volta*: +/- " & TEXT(((D11*1.5)/1440),"h:mm") & "h | " & D11 & "km" )} -> - TRATOR: *1BM5060EAP4104558*_x000D_ - _x000D_ - *Cliente*: MANUTENÇÃO → CLIENTE -NF 45965_x000D_ - *Obs:* LUCIANO DE FREITAS - 43 99624-6946_x000D_ - *De*: https://maps.app.goo.gl/PXTmMqoYPtx48Gex6_x000D_ - *Para*: MACPONTA AGRO DE ARAPOTI_x000D_ - *Ida e volta*: +/- 4:37h | 185km
A12: CONCLUIDO | B12: PROPRIO DAF | C12: =IFERROR((D12*1.5)/1440, "?") -> 0.053125 | D12: 51 | E12: =IFERROR((D12*6),"?") -> 306 | G12: 1BM7215CVR3000057 | H12: 45966 | I12: 45967 | J12: MANUTENÇÃO → CLIENTE | K12: marcelo.ferreira | L12: PONTA GROSSA | M12: CLIENTE | N12: DE LOJA PARA CLIENTE | O12: MPA | P12: https://maps.app.goo.gl/pQZUg9LPg5sgdyLs8 | Q12: GABRIEL - 42 -99972-7464 | R12: PONTA GROSSA | S12: TRATOR | T12: =IF( OR( IFERROR(FIND("BM",G12),0)>0, IFERROR(FIND("PY",G12),0)>0 ), MID(TRIM(SUBSTITUTE(SUBSTITUTE(G12,CHAR(160),""),CHAR(9),"")),4,5), MID(TRIM(SUBSTITUTE(SUBSTITUTE(G12,CHAR(160),""),CHAR(9),"")),4,4) ) -> 7215C | U12: {=_xlfn.LET( _xlpm.ch, TRIM(SUBSTITUTE(G12,CHAR(160),"")), _xlpm.ehTrator, OR(IFERROR(FIND("BM",_xlpm.ch),0)>0, IFERROR(FIND("PY",_xlpm.ch),0)>0), _xlpm.chave, IF(_xlpm.ehTrator, MID(_xlpm.ch,4,5), MID(_xlpm.ch,4,4)), _xlpm.fonte, IF(LEN(_xlpm.chave)=5, UTIL!BS:BS, UTIL!BR:BR), _xlpm.modelo, TRIM(SUBSTITUTE(T12,CHAR(160),"")), _xlpm.nomeMod, IFERROR(_xlfn.XLOOKUP("*"&_xlpm.modelo&"*", UTIL!D:D, UTIL!B:B, "", 2), IFERROR(_xlfn.XLOOKUP("*"&_xlpm.modelo&"*", UTIL!E:E, UTIL!B:B, "", 2), "")), _xlpm.tipoMod, IF(_xlpm.nomeMod="", "", IFERROR(LEFT(_xlpm.nomeMod, FIND(" ", _xlpm.nomeMod)-1), _xlpm.nomeMod)), _xlpm.dimMod, IFERROR(_xlfn.XLOOKUP("*"&_xlpm.modelo&"*", UTIL!D:D, UTIL!K:K, "", 2), IFERROR(_xlfn.XLOOKUP("*"&_xlpm.modelo&"*", UTIL!E:E, UTIL!K:K, "", 2), "")), _xlpm.tipotxt_antigo, IF(_xlpm.ehTrator, "TRATOR", IFERROR(_xlfn.XLOOKUP(_xlpm.chave, _xlpm.fonte, UTIL!BP:BP, "", 0), IFERROR(_xlfn.XLOOKUP("*"&_xlpm.chave&"*", _xlpm.fonte, UTIL!BP:BP, "", 2), "Não encontrado"))), _xlpm.dimtxt_antigo, IFERROR(_xlfn.XLOOKUP(_xlpm.chave, _xlpm.fonte, UTIL!BY:BY, "", 0), IFERROR(_xlfn.XLOOKUP("*"&_xlpm.chave&"*", _xlpm.fonte, UTIL!BY:BY, "", 2), "Não encontrado")), _xlpm.tipotxt, IF(_xlpm.tipoMod<>"", _xlpm.tipoMod, _xlpm.tipotxt_antigo), _xlpm.dimtxt, IF(_xlpm.dimMod<>"", _xlpm.dimMod, _xlpm.dimtxt_antigo), _xlpm.deTxt, IF(L12="CLIENTE", O12, IF(LEFT(L12,4)="http", L12, "MACPONTA AGRO DE "&L12)), _xlpm.paraBase, IF(M12="CLIENTE", P12, M12), _xlpm.paraTxt, IF(LEFT(_xlpm.paraBase,4)="http", _xlpm.paraBase, "MACPONTA AGRO DE "&_xlpm.paraBase), _xlpm.nfParte, IF(LEN(TRIM(I12))=0, "", " -NF "&TRIM(I12)), "- " & _xlpm.tipotxt & ": *" & G12 & "*" & CHAR(13)&CHAR(10) & "- " & _xlpm.dimtxt & CHAR(13)&CHAR(10) & "- *Cliente*: " & J12 & _xlpm.nfParte & CHAR(13)&CHAR(10) & "- *Obs:* " & Q12 & CHAR(13)&CHAR(10) & CHAR(10) & "- *De*: " & _xlpm.deTxt & CHAR(13)&CHAR(10) & "- *Para*: " & _xlpm.paraTxt & CHAR(13)&CHAR(10) & "- *Ida e volta*: +/- " & TEXT(((D12*1.5)/1440),"h:mm") & "h | " & D12 & "km" )} -> - TRATOR: *1BM7215CVR3000057*_x000D_ - _x000D_ - *Cliente*: MANUTENÇÃO → CLIENTE -NF 45967_x000D_ - *Obs:* GABRIEL - 42 -99972-7464_x000D_ - *De*: MACPONTA AGRO DE PONTA GROSSA_x000D_ - *Para*: https://maps.app.goo.gl/pQZUg9LPg5sgdyLs8_x000D_ - *Ida e volta*: +/- 1:16h | 51km
A13: CONCLUIDO | B13: PROPRIO VW | C13: =IFERROR((D13*1.5)/1440, "?") -> 0.022916667 | D13: 22 | E13: =IFERROR((D13*6),"?") -> 132 | G13: 1P06110DABA021136 | H13: 45966 | I13: 45967 | J13: MANUTENÇÃO → CLIENTE | K13: leonardo.ramos | L13: PONTA GROSSA | M13: CLIENTE | N13: DE LOJA PARA CLIENTE | O13: MPA | P13: https://maps.app.goo.gl/zzmzdRt4m8WXMVjg9 | Q13: JUNIOR +55 42 8866-3271 | R13: PONTA GROSSA | S13: PULVERIZADOR | T13: =IF( OR( IFERROR(FIND("BM",G13),0)>0, IFERROR(FIND("PY",G13),0)>0 ), MID(TRIM(SUBSTITUTE(SUBSTITUTE(G13,CHAR(160),""),CHAR(9),"")),4,5), MID(TRIM(SUBSTITUTE(SUBSTITUTE(G13,CHAR(160),""),CHAR(9),"")),4,4) ) -> 6110 | U13: {=_xlfn.LET( _xlpm.ch, TRIM(SUBSTITUTE(G13,CHAR(160),"")), _xlpm.ehTrator, OR(IFERROR(FIND("BM",_xlpm.ch),0)>0, IFERROR(FIND("PY",_xlpm.ch),0)>0), _xlpm.chave, IF(_xlpm.ehTrator, MID(_xlpm.ch,4,5), MID(_xlpm.ch,4,4)), _xlpm.fonte, IF(LEN(_xlpm.chave)=5, UTIL!BS:BS, UTIL!BR:BR), _xlpm.modelo, TRIM(SUBSTITUTE(T13,CHAR(160),"")), _xlpm.nomeMod, IFERROR(_xlfn.XLOOKUP("*"&_xlpm.modelo&"*", UTIL!D:D, UTIL!B:B, "", 2), IFERROR(_xlfn.XLOOKUP("*"&_xlpm.modelo&"*", UTIL!E:E, UTIL!B:B, "", 2), "")), _xlpm.tipoMod, IF(_xlpm.nomeMod="", "", IFERROR(LEFT(_xlpm.nomeMod, FIND(" ", _xlpm.nomeMod)-1), _xlpm.nomeMod)), _xlpm.dimMod, IFERROR(_xlfn.XLOOKUP("*"&_xlpm.modelo&"*", UTIL!D:D, UTIL!K:K, "", 2), IFERROR(_xlfn.XLOOKUP("*"&_xlpm.modelo&"*", UTIL!E:E, UTIL!K:K, "", 2), "")), _xlpm.tipotxt_antigo, IF(_xlpm.ehTrator, "TRATOR", IFERROR(_xlfn.XLOOKUP(_xlpm.chave, _xlpm.fonte, UTIL!BP:BP, "", 0), IFERROR(_xlfn.XLOOKUP("*"&_xlpm.chave&"*", _xlpm.fonte, UTIL!BP:BP, "", 2), "Não encontrado"))), _xlpm.dimtxt_antigo, IFERROR(_xlfn.XLOOKUP(_xlpm.chave, _xlpm.fonte, UTIL!BY:BY, "", 0), IFERROR(_xlfn.XLOOKUP("*"&_xlpm.chave&"*", _xlpm.fonte, UTIL!BY:BY, "", 2), "Não encontrado")), _xlpm.tipotxt, IF(_xlpm.tipoMod<>"", _xlpm.tipoMod, _xlpm.tipotxt_antigo), _xlpm.dimtxt, IF(_xlpm.dimMod<>"", _xlpm.dimMod, _xlpm.dimtxt_antigo), _xlpm.deTxt, IF(L13="CLIENTE", O13, IF(LEFT(L13,4)="http", L13, "MACPONTA AGRO DE "&L13)), _xlpm.paraBase, IF(M13="CLIENTE", P13, M13), _xlpm.paraTxt, IF(LEFT(_xlpm.paraBase,4)="http", _xlpm.paraBase, "MACPONTA AGRO DE "&_xlpm.paraBase), _xlpm.nfParte, IF(LEN(TRIM(I13))=0, "", " -NF "&TRIM(I13)), "- " & _xlpm.tipotxt & ": *" & G13 & "*" & CHAR(13)&CHAR(10) & "- " & _xlpm.dimtxt & CHAR(13)&CHAR(10) & "- *Cliente*: " & J13 & _xlpm.nfParte & CHAR(13)&CHAR(10) & "- *Obs:* " & Q13 & CHAR(13)&CHAR(10) & CHAR(10) & "- *De*: " & _xlpm.deTxt & CHAR(13)&CHAR(10) & "- *Para*: " & _xlpm.paraTxt & CHAR(13)&CHAR(10) & "- *Ida e volta*: +/- " & TEXT(((D13*1.5)/1440),"h:mm") & "h | " & D13 & "km" )} -> - : *1P06110DABA021136*_x000D_ - _x000D_ - *Cliente*: MANUTENÇÃO → CLIENTE -NF 45967_x000D_ - *Obs:* JUNIOR +55 42 8866-3271_x000D_ - *De*: MACPONTA AGRO DE PONTA GROSSA_x000D_ - *Para*: https://maps.app.goo.gl/zzmzdRt4m8WXMVjg9_x000D_ - *Ida e volta*: +/- 0:33h | 22km
A14: CONCLUIDO | B14: TERCEIRO MAZETTO | C14: =IFERROR((D14*1.5)/1440, "?") -> 0.16666667 | D14: 160 | F14: 1458 | G14: 1BM6135MASH000623 | H14: 45966 | I14: 45966 | J14: VLADEMIR STORTI -NF107917 | K14: euclides.junior | L14: GUARAPUAVA | M14: CLIENTE | N14: DE LOJA PARA CLIENTE | O14: MPA | P14: https://maps.app.goo.gl/giUyNXP6omVdANbb6 | Q14: Vladmir | R14: GUARAPUAVA | S14: TRATOR | T14: =IF( OR( IFERROR(FIND("BM",G14),0)>0, IFERROR(FIND("PY",G14),0)>0 ), MID(TRIM(SUBSTITUTE(SUBSTITUTE(G14,CHAR(160),""),CHAR(9),"")),4,5), MID(TRIM(SUBSTITUTE(SUBSTITUTE(G14,CHAR(160),""),CHAR(9),"")),4,4) ) -> 6135M | U14: {=_xlfn.LET( _xlpm.ch, TRIM(SUBSTITUTE(G14,CHAR(160),"")), _xlpm.ehTrator, OR(IFERROR(FIND("BM",_xlpm.ch),0)>0, IFERROR(FIND("PY",_xlpm.ch),0)>0), _xlpm.chave, IF(_xlpm.ehTrator, MID(_xlpm.ch,4,5), MID(_xlpm.ch,4,4)), _xlpm.fonte, IF(LEN(_xlpm.chave)=5, UTIL!BS:BS, UTIL!BR:BR), _xlpm.modelo, TRIM(SUBSTITUTE(T14,CHAR(160),"")), _xlpm.nomeMod, IFERROR(_xlfn.XLOOKUP("*"&_xlpm.modelo&"*", UTIL!D:D, UTIL!B:B, "", 2), IFERROR(_xlfn.XLOOKUP("*"&_xlpm.modelo&"*", UTIL!E:E, UTIL!B:B, "", 2), "")), _xlpm.tipoMod, IF(_xlpm.nomeMod="", "", IFERROR(LEFT(_xlpm.nomeMod, FIND(" ", _xlpm.nomeMod)-1), _xlpm.nomeMod)), _xlpm.dimMod, IFERROR(_xlfn.XLOOKUP("*"&_xlpm.modelo&"*", UTIL!D:D, UTIL!K:K, "", 2), IFERROR(_xlfn.XLOOKUP("*"&_xlpm.modelo&"*", UTIL!E:E, UTIL!K:K, "", 2), "")), _xlpm.tipotxt_antigo, IF(_xlpm.ehTrator, "TRATOR", IFERROR(_xlfn.XLOOKUP(_xlpm.chave, _xlpm.fonte, UTIL!BP:BP, "", 0), IFERROR(_xlfn.XLOOKUP("*"&_xlpm.chave&"*", _xlpm.fonte, UTIL!BP:BP, "", 2), "Não encontrado"))), _xlpm.dimtxt_antigo, IFERROR(_xlfn.XLOOKUP(_xlpm.chave, _xlpm.fonte, UTIL!BY:BY, "", 0), IFERROR(_xlfn.XLOOKUP("*"&_xlpm.chave&"*", _xlpm.fonte, UTIL!BY:BY, "", 2), "Não encontrado")), _xlpm.tipotxt, IF(_xlpm.tipoMod<>"", _xlpm.tipoMod, _xlpm.tipotxt_antigo), _xlpm.dimtxt, IF(_xlpm.dimMod<>"", _xlpm.dimMod, _xlpm.dimtxt_antigo), _xlpm.deTxt, IF(L14="CLIENTE", O14, IF(LEFT(L14,4)="http", L14, "MACPONTA AGRO DE "&L14)), _xlpm.paraBase, IF(M14="CLIENTE", P14, M14), _xlpm.paraTxt, IF(LEFT(_xlpm.paraBase,4)="http", _xlpm.paraBase, "MACPONTA AGRO DE "&_xlpm.paraBase), _xlpm.nfParte, IF(LEN(TRIM(I14))=0, "", " -NF "&TRIM(I14)), "- " & _xlpm.tipotxt & ": *" & G14 & "*" & CHAR(13)&CHAR(10) & "- " & _xlpm.dimtxt & CHAR(13)&CHAR(10) & "- *Cliente*: " & J14 & _xlpm.nfParte & CHAR(13)&CHAR(10) & "- *Obs:* " & Q14 & CHAR(13)&CHAR(10) & CHAR(10) & "- *De*: " & _xlpm.deTxt & CHAR(13)&CHAR(10) & "- *Para*: " & _xlpm.paraTxt & CHAR(13)&CHAR(10) & "- *Ida e volta*: +/- " & TEXT(((D14*1.5)/1440),"h:mm") & "h | " & D14 & "km" )} -> - TRATOR: *1BM6135MASH000623*_x000D_ - _x000D_ - *Cliente*: VLADEMIR STORTI -NF107917 -NF 45966_x000D_ - *Obs:* Vladmir_x000D_ - *De*: MACPONTA AGRO DE GUARAPUAVA_x000D_ - *Para*: https://maps.app.goo.gl/giUyNXP6omVdANbb6_x000D_ - *Ida e volta*: +/- 4:00h | 160km
A15: CONCLUIDO | B15: TERCEIRO NELSON | C15: =IFERROR((D15*1.5)/1440, "?") -> 0.13541667 | D15: 130 | F15: 975 | G15: 1BM5080EKS4203735 | H15: 45966 | I15: 45966 | J15: VERIDIANA POSS DE LIMA -NF61217 | K15: josiane.oliveira | L15: ARAPOTI | M15: CLIENTE | N15: DE LOJA PARA CLIENTE | O15: MPA | P15: https://maps.app.goo.gl/oLpnxFw9huVdueSf7 | Q15: Veridiana 043984053787 -CEN Alison Russi | R15: ARAPOTI | S15: TRATOR | T15: =IF( OR( IFERROR(FIND("BM",G15),0)>0, IFERROR(FIND("PY",G15),0)>0 ), MID(TRIM(SUBSTITUTE(SUBSTITUTE(G15,CHAR(160),""),CHAR(9),"")),4,5), MID(TRIM(SUBSTITUTE(SUBSTITUTE(G15,CHAR(160),""),CHAR(9),"")),4,4) ) -> 5080E | U15: {=_xlfn.LET( _xlpm.ch, TRIM(SUBSTITUTE(G15,CHAR(160),"")), _xlpm.ehTrator, OR(IFERROR(FIND("BM",_xlpm.ch),0)>0, IFERROR(FIND("PY",_xlpm.ch),0)>0), _xlpm.chave, IF(_xlpm.ehTrator, MID(_xlpm.ch,4,5), MID(_xlpm.ch,4,4)), _xlpm.fonte, IF(LEN(_xlpm.chave)=5, UTIL!BS:BS, UTIL!BR:BR), _xlpm.modelo, TRIM(SUBSTITUTE(T15,CHAR(160),"")), _xlpm.nomeMod, IFERROR(_xlfn.XLOOKUP("*"&_xlpm.modelo&"*", UTIL!D:D, UTIL!B:B, "", 2), IFERROR(_xlfn.XLOOKUP("*"&_xlpm.modelo&"*", UTIL!E:E, UTIL!B:B, "", 2), "")), _xlpm.tipoMod, IF(_xlpm.nomeMod="", "", IFERROR(LEFT(_xlpm.nomeMod, FIND(" ", _xlpm.nomeMod)-1), _xlpm.nomeMod)), _xlpm.dimMod, IFERROR(_xlfn.XLOOKUP("*"&_xlpm.modelo&"*", UTIL!D:D, UTIL!K:K, "", 2), IFERROR(_xlfn.XLOOKUP("*"&_xlpm.modelo&"*", UTIL!E:E, UTIL!K:K, "", 2), "")), _xlpm.tipotxt_antigo, IF(_xlpm.ehTrator, "TRATOR", IFERROR(_xlfn.XLOOKUP(_xlpm.chave, _xlpm.fonte, UTIL!BP:BP, "", 0), IFERROR(_xlfn.XLOOKUP("*"&_xlpm.chave&"*", _xlpm.fonte, UTIL!BP:BP, "", 2), "Não encontrado"))), _xlpm.dimtxt_antigo, IFERROR(_xlfn.XLOOKUP(_xlpm.chave, _xlpm.fonte, UTIL!BY:BY, "", 0), IFERROR(_xlfn.XLOOKUP("*"&_xlpm.chave&"*", _xlpm.fonte, UTIL!BY:BY, "", 2), "Não encontrado")), _xlpm.tipotxt, IF(_xlpm.tipoMod<>"", _xlpm.tipoMod, _xlpm.tipotxt_antigo), _xlpm.dimtxt, IF(_xlpm.dimMod<>"", _xlpm.dimMod, _xlpm.dimtxt_antigo), _xlpm.deTxt, IF(L15="CLIENTE", O15, IF(LEFT(L15,4)="http", L15, "MACPONTA AGRO DE "&L15)), _xlpm.paraBase, IF(M15="CLIENTE", P15, M15), _xlpm.paraTxt, IF(LEFT(_xlpm.paraBase,4)="http", _xlpm.paraBase, "MACPONTA AGRO DE "&_xlpm.paraBase), _xlpm.nfParte, IF(LEN(TRIM(I15))=0, "", " -NF "&TRIM(I15)), "- " & _xlpm.tipotxt & ": *" & G15 & "*" & CHAR(13)&CHAR(10) & "- " & _xlpm.dimtxt & CHAR(13)&CHAR(10) & "- *Cliente*: " & J15 & _xlpm.nfParte & CHAR(13)&CHAR(10) & "- *Obs:* " & Q15 & CHAR(13)&CHAR(10) & CHAR(10) & "- *De*: " & _xlpm.deTxt & CHAR(13)&CHAR(10) & "- *Para*: " & _xlpm.paraTxt & CHAR(13)&CHAR(10) & "- *Ida e volta*: +/- " & TEXT(((D15*1.5)/1440),"h:mm") & "h | " & D15 & "km" )} -> - TRATOR: *1BM5080EKS4203735*_x000D_ - _x000D_ - *Cliente*: VERIDIANA POSS DE LIMA -NF61217 -NF 45966_x000D_ - *Obs:* Veridiana 043984053787 -CEN Alison Russi_x000D_ - *De*: MACPONTA AGRO DE ARAPOTI_x000D_ - *Para*: https://maps.app.goo.gl/oLpnxFw9huVdueSf7_x000D_ - *Ida e volta*: +/- 3:15h | 130km
A16: CONCLUIDO (D) | B16: PROPRIO DAF | C16: =IFERROR((D16*1.5)/1440, "?") -> 0.15625 | D16: 150 | E16: 500 | G16: 1CQ0630AHR0155127 | H16: 45966 | I16: 45966 | J16: MARCELO RIBEIRO DE NARDI -NF278794 | K16: marcos.ribas | L16: PONTA GROSSA | M16: CLIENTE | N16: DE LOJA PARA CLIENTE | O16: MPA | P16: https://maps.app.goo.gl/2DJawZBMR4yqycss9 | Q16: DANILO - MARCELO | R16: PONTA GROSSA | S16: PLATAFORMA | T16: =IF( OR( IFERROR(FIND("BM",G16),0)>0, IFERROR(FIND("PY",G16),0)>0 ), MID(TRIM(SUBSTITUTE(SUBSTITUTE(G16,CHAR(160),""),CHAR(9),"")),4,5), MID(TRIM(SUBSTITUTE(SUBSTITUTE(G16,CHAR(160),""),CHAR(9),"")),4,4) ) -> 0630 | U16: {=_xlfn.LET( _xlpm.ch, TRIM(SUBSTITUTE(G16,CHAR(160),"")), _xlpm.ehTrator, OR(IFERROR(FIND("BM",_xlpm.ch),0)>0, IFERROR(FIND("PY",_xlpm.ch),0)>0), _xlpm.chave, IF(_xlpm.ehTrator, MID(_xlpm.ch,4,5), MID(_xlpm.ch,4,4)), _xlpm.fonte, IF(LEN(_xlpm.chave)=5, UTIL!BS:BS, UTIL!BR:BR), _xlpm.modelo, TRIM(SUBSTITUTE(T16,CHAR(160),"")), _xlpm.nomeMod, IFERROR(_xlfn.XLOOKUP("*"&_xlpm.modelo&"*", UTIL!D:D, UTIL!B:B, "", 2), IFERROR(_xlfn.XLOOKUP("*"&_xlpm.modelo&"*", UTIL!E:E, UTIL!B:B, "", 2), "")), _xlpm.tipoMod, IF(_xlpm.nomeMod="", "", IFERROR(LEFT(_xlpm.nomeMod, FIND(" ", _xlpm.nomeMod)-1), _xlpm.nomeMod)), _xlpm.dimMod, IFERROR(_xlfn.XLOOKUP("*"&_xlpm.modelo&"*", UTIL!D:D, UTIL!K:K, "", 2), IFERROR(_xlfn.XLOOKUP("*"&_xlpm.modelo&"*", UTIL!E:E, UTIL!K:K, "", 2), "")), _xlpm.tipotxt_antigo, IF(_xlpm.ehTrator, "TRATOR", IFERROR(_xlfn.XLOOKUP(_xlpm.chave, _xlpm.fonte, UTIL!BP:BP, "", 0), IFERROR(_xlfn.XLOOKUP("*"&_xlpm.chave&"*", _xlpm.fonte, UTIL!BP:BP, "", 2), "Não encontrado"))), _xlpm.dimtxt_antigo, IFERROR(_xlfn.XLOOKUP(_xlpm.chave, _xlpm.fonte, UTIL!BY:BY, "", 0), IFERROR(_xlfn.XLOOKUP("*"&_xlpm.chave&"*", _xlpm.fonte, UTIL!BY:BY, "", 2), "Não encontrado")), _xlpm.tipotxt, IF(_xlpm.tipoMod<>"", _xlpm.tipoMod, _xlpm.tipotxt_antigo), _xlpm.dimtxt, IF(_xlpm.dimMod<>"", _xlpm.dimMod, _xlpm.dimtxt_antigo), _xlpm.deTxt, IF(L16="CLIENTE", O16, IF(LEFT(L16,4)="http", L16, "MACPONTA AGRO DE "&L16)), _xlpm.paraBase, IF(M16="CLIENTE", P16, M16), _xlpm.paraTxt, IF(LEFT(_xlpm.paraBase,4)="http", _xlpm.paraBase, "MACPONTA AGRO DE "&_xlpm.paraBase), _xlpm.nfParte, IF(LEN(TRIM(I16))=0, "", " -NF "&TRIM(I16)), "- " & _xlpm.tipotxt & ": *" & G16 & "*" & CHAR(13)&CHAR(10) & "- " & _xlpm.dimtxt & CHAR(13)&CHAR(10) & "- *Cliente*: " & J16 & _xlpm.nfParte & CHAR(13)&CHAR(10) & "- *Obs:* " & Q16 & CHAR(13)&CHAR(10) & CHAR(10) & "- *De*: " & _xlpm.deTxt & CHAR(13)&CHAR(10) & "- *Para*: " & _xlpm.paraTxt & CHAR(13)&CHAR(10) & "- *Ida e volta*: +/- " & TEXT(((D16*1.5)/1440),"h:mm") & "h | " & D16 & "km" )} -> - PLATAFORMA: *1CQ0630AHR0155127*_x000D_ - A:1,60 x C:9,14 x L:1,80-1,80 x P:2.871kg_x000D_ - *Cliente*: MARCELO RIBEIRO DE NARDI -NF278794 -NF 45966_x000D_ - *Obs:* DANILO - MARCELO _x000D_ - *De*: MACPONTA AGRO DE PONTA GROSSA_x000D_ - *Para*: https://maps.app.goo.gl/2DJawZBMR4yqycss9_x000D_ - *Ida e volta*: +/- 3:45h | 150km
A17: CONCLUIDO (D) | B17: PROPRIO DAF | C17: =IFERROR((D17*1.5)/1440, "?") -> 0.15625 | D17: 150 | E17: 500 | G17: 1CQS550AER0155105 | H17: 45966 | I17: 45966 | J17: MARCELO RIBEIRO DE NARDI -NF278794 | K17: marcos.ribas | L17: PONTA GROSSA | M17: CLIENTE | N17: DE LOJA PARA CLIENTE | O17: MPA | P17: https://maps.app.goo.gl/2DJawZBMR4yqycss9 | Q17: DANILO - MARCELO | R17: PONTA GROSSA | S17: COLHEITADEIRA | T17: =IF( OR( IFERROR(FIND("BM",G17),0)>0, IFERROR(FIND("PY",G17),0)>0 ), MID(TRIM(SUBSTITUTE(SUBSTITUTE(G17,CHAR(160),""),CHAR(9),"")),4,5), MID(TRIM(SUBSTITUTE(SUBSTITUTE(G17,CHAR(160),""),CHAR(9),"")),4,4) ) -> S550 | U17: {=_xlfn.LET( _xlpm.ch, TRIM(SUBSTITUTE(G17,CHAR(160),"")), _xlpm.ehTrator, OR(IFERROR(FIND("BM",_xlpm.ch),0)>0, IFERROR(FIND("PY",_xlpm.ch),0)>0), _xlpm.chave, IF(_xlpm.ehTrator, MID(_xlpm.ch,4,5), MID(_xlpm.ch,4,4)), _xlpm.fonte, IF(LEN(_xlpm.chave)=5, UTIL!BS:BS, UTIL!BR:BR), _xlpm.modelo, TRIM(SUBSTITUTE(T17,CHAR(160),"")), _xlpm.nomeMod, IFERROR(_xlfn.XLOOKUP("*"&_xlpm.modelo&"*", UTIL!D:D, UTIL!B:B, "", 2), IFERROR(_xlfn.XLOOKUP("*"&_xlpm.modelo&"*", UTIL!E:E, UTIL!B:B, "", 2), "")), _xlpm.tipoMod, IF(_xlpm.nomeMod="", "", IFERROR(LEFT(_xlpm.nomeMod, FIND(" ", _xlpm.nomeMod)-1), _xlpm.nomeMod)), _xlpm.dimMod, IFERROR(_xlfn.XLOOKUP("*"&_xlpm.modelo&"*", UTIL!D:D, UTIL!K:K, "", 2), IFERROR(_xlfn.XLOOKUP("*"&_xlpm.modelo&"*", UTIL!E:E, UTIL!K:K, "", 2), "")), _xlpm.tipotxt_antigo, IF(_xlpm.ehTrator, "TRATOR", IFERROR(_xlfn.XLOOKUP(_xlpm.chave, _xlpm.fonte, UTIL!BP:BP, "", 0), IFERROR(_xlfn.XLOOKUP("*"&_xlpm.chave&"*", _xlpm.fonte, UTIL!BP:BP, "", 2), "Não encontrado"))), _xlpm.dimtxt_antigo, IFERROR(_xlfn.XLOOKUP(_xlpm.chave, _xlpm.fonte, UTIL!BY:BY, "", 0), IFERROR(_xlfn.XLOOKUP("*"&_xlpm.chave&"*", _xlpm.fonte, UTIL!BY:BY, "", 2), "Não encontrado")), _xlpm.tipotxt, IF(_xlpm.tipoMod<>"", _xlpm.tipoMod, _xlpm.tipotxt_antigo), _xlpm.dimtxt, IF(_xlpm.dimMod<>"", _xlpm.dimMod, _xlpm.dimtxt_antigo), _xlpm.deTxt, IF(L17="CLIENTE", O17, IF(LEFT(L17,4)="http", L17, "MACPONTA AGRO DE "&L17)), _xlpm.paraBase, IF(M17="CLIENTE", P17, M17), _xlpm.paraTxt, IF(LEFT(_xlpm.paraBase,4)="http", _xlpm.paraBase, "MACPONTA AGRO DE "&_xlpm.paraBase), _xlpm.nfParte, IF(LEN(TRIM(I17))=0, "", " -NF "&TRIM(I17)), "- " & _xlpm.tipotxt & ": *" & G17 & "*" & CHAR(13)&CHAR(10) & "- " & _xlpm.dimtxt & CHAR(13)&CHAR(10) & "- *Cliente*: " & J17 & _xlpm.nfParte & CHAR(13)&CHAR(10) & "- *Obs:* " & Q17 & CHAR(13)&CHAR(10) & CHAR(10) & "- *De*: " & _xlpm.deTxt & CHAR(13)&CHAR(10) & "- *Para*: " & _xlpm.paraTxt & CHAR(13)&CHAR(10) & "- *Ida e volta*: +/- " & TEXT(((D17*1.5)/1440),"h:mm") & "h | " & D17 & "km" )} -> - COLHEITADEIRA: *1CQS550AER0155105*_x000D_ - A:3,80 x C:10,00 x L:3,70-4,20 x P:15.938kg_x000D_ - *Cliente*: MARCELO RIBEIRO DE NARDI -NF278794 -NF 45966_x000D_ - *Obs:* DANILO - MARCELO _x000D_ - *De*: MACPONTA AGRO DE PONTA GROSSA_x000D_ - *Para*: https://maps.app.goo.gl/2DJawZBMR4yqycss9_x000D_ - *Ida e volta*: +/- 3:45h | 150km
A18: CONCLUIDO | B18: PROPRIO VW | C18: =IFERROR((D18*1.5)/1440, "?") -> 0.25520833 | D18: 245 | E18: =IFERROR((D18*6),"?") -> 1470 | G18: 1BM6135MCSH000563 | H18: 45967 | I18: 45967 | J18: WILLEM HENDRIK VAN DE RIET -NF109953 | K18: fernando.wiesinies | L18: IRATI | M18: CLIENTE | N18: DE LOJA PARA CLIENTE | O18: MPA | P18: https://maps.app.goo.gl/B5W3gFAkVjKrxcms8 | Q18: (42)999730047 Willen | R18: IRATI | S18: TRATOR | T18: =IF( OR( IFERROR(FIND("BM",G18),0)>0, IFERROR(FIND("PY",G18),0)>0 ), MID(TRIM(SUBSTITUTE(SUBSTITUTE(G18,CHAR(160),""),CHAR(9),"")),4,5), MID(TRIM(SUBSTITUTE(SUBSTITUTE(G18,CHAR(160),""),CHAR(9),"")),4,4) ) -> 6135M | U18: {=_xlfn.LET( _xlpm.ch, TRIM(SUBSTITUTE(G18,CHAR(160),"")), _xlpm.ehTrator, OR(IFERROR(FIND("BM",_xlpm.ch),0)>0, IFERROR(FIND("PY",_xlpm.ch),0)>0), _xlpm.chave, IF(_xlpm.ehTrator, MID(_xlpm.ch,4,5), MID(_xlpm.ch,4,4)), _xlpm.fonte, IF(LEN(_xlpm.chave)=5, UTIL!BS:BS, UTIL!BR:BR), _xlpm.modelo, TRIM(SUBSTITUTE(T18,CHAR(160),"")), _xlpm.nomeMod, IFERROR(_xlfn.XLOOKUP("*"&_xlpm.modelo&"*", UTIL!D:D, UTIL!B:B, "", 2), IFERROR(_xlfn.XLOOKUP("*"&_xlpm.modelo&"*", UTIL!E:E, UTIL!B:B, "", 2), "")), _xlpm.tipoMod, IF(_xlpm.nomeMod="", "", IFERROR(LEFT(_xlpm.nomeMod, FIND(" ", _xlpm.nomeMod)-1), _xlpm.nomeMod)), _xlpm.dimMod, IFERROR(_xlfn.XLOOKUP("*"&_xlpm.modelo&"*", UTIL!D:D, UTIL!K:K, "", 2), IFERROR(_xlfn.XLOOKUP("*"&_xlpm.modelo&"*", UTIL!E:E, UTIL!K:K, "", 2), "")), _xlpm.tipotxt_antigo, IF(_xlpm.ehTrator, "TRATOR", IFERROR(_xlfn.XLOOKUP(_xlpm.chave, _xlpm.fonte, UTIL!BP:BP, "", 0), IFERROR(_xlfn.XLOOKUP("*"&_xlpm.chave&"*", _xlpm.fonte, UTIL!BP:BP, "", 2), "Não encontrado"))), _xlpm.dimtxt_antigo, IFERROR(_xlfn.XLOOKUP(_xlpm.chave, _xlpm.fonte, UTIL!BY:BY, "", 0), IFERROR(_xlfn.XLOOKUP("*"&_xlpm.chave&"*", _xlpm.fonte, UTIL!BY:BY, "", 2), "Não encontrado")), _xlpm.tipotxt, IF(_xlpm.tipoMod<>"", _xlpm.tipoMod, _xlpm.tipotxt_antigo), _xlpm.dimtxt, IF(_xlpm.dimMod<>"", _xlpm.dimMod, _xlpm.dimtxt_antigo), _xlpm.deTxt, IF(L18="CLIENTE", O18, IF(LEFT(L18,4)="http", L18, "MACPONTA AGRO DE "&L18)), _xlpm.paraBase, IF(M18="CLIENTE", P18, M18), _xlpm.paraTxt, IF(LEFT(_xlpm.paraBase,4)="http", _xlpm.paraBase, "MACPONTA AGRO DE "&_xlpm.paraBase), _xlpm.nfParte, IF(LEN(TRIM(I18))=0, "", " -NF "&TRIM(I18)), "- " & _xlpm.tipotxt & ": *" & G18 & "*" & CHAR(13)&CHAR(10) & "- " & _xlpm.dimtxt & CHAR(13)&CHAR(10) & "- *Cliente*: " & J18 & _xlpm.nfParte & CHAR(13)&CHAR(10) & "- *Obs:* " & Q18 & CHAR(13)&CHAR(10) & CHAR(10) & "- *De*: " & _xlpm.deTxt & CHAR(13)&CHAR(10) & "- *Para*: " & _xlpm.paraTxt & CHAR(13)&CHAR(10) & "- *Ida e volta*: +/- " & TEXT(((D18*1.5)/1440),"h:mm") & "h | " & D18 & "km" )} -> - TRATOR: *1BM6135MCSH000563*_x000D_ - _x000D_ - *Cliente*: WILLEM HENDRIK VAN DE RIET -NF109953 -NF 45967_x000D_ - *Obs:* (42)999730047 Willen _x000D_ - *De*: MACPONTA AGRO DE IRATI_x000D_ - *Para*: https://maps.app.goo.gl/B5W3gFAkVjKrxcms8_x000D_ - *Ida e volta*: +/- 6:07h | 245km
A19: CONCLUIDO | B19: PROPRIO DAF | C19: =IFERROR((D19*1.5)/1440, "?") -> 0.18229167 | D19: 175 | E19: =IFERROR((D19*6),"?") -> 1050 | G19: 1CQS680ATF0110209 | H19: 45968 | I19: 45969 | J19: DOUGLAS FANCHIN TAQUES FONSECA -NF278835 | K19: marcelo.ferreira | L19: PONTA GROSSA | M19: CLIENTE | N19: DE LOJA PARA CLIENTE | O19: MPA | P19: https://maps.app.goo.gl/GfTKV558G2iXHWmg8 | Q19: VALTINHO 42-99920-3056 | R19: PONTA GROSSA | S19: COLHEITADEIRA | T19: =IF( OR( IFERROR(FIND("BM",G19),0)>0, IFERROR(FIND("PY",G19),0)>0 ), MID(TRIM(SUBSTITUTE(SUBSTITUTE(G19,CHAR(160),""),CHAR(9),"")),4,5), MID(TRIM(SUBSTITUTE(SUBSTITUTE(G19,CHAR(160),""),CHAR(9),"")),4,4) ) -> S680 | U19: {=_xlfn.LET( _xlpm.ch, TRIM(SUBSTITUTE(G19,CHAR(160),"")), _xlpm.ehTrator, OR(IFERROR(FIND("BM",_xlpm.ch),0)>0, IFERROR(FIND("PY",_xlpm.ch),0)>0), _xlpm.chave, IF(_xlpm.ehTrator, MID(_xlpm.ch,4,5), MID(_xlpm.ch,4,4)), _xlpm.fonte, IF(LEN(_xlpm.chave)=5, UTIL!BS:BS, UTIL!BR:BR), _xlpm.modelo, TRIM(SUBSTITUTE(T19,CHAR(160),"")), _xlpm.nomeMod, IFERROR(_xlfn.XLOOKUP("*"&_xlpm.modelo&"*", UTIL!D:D, UTIL!B:B, "", 2), IFERROR(_xlfn.XLOOKUP("*"&_xlpm.modelo&"*", UTIL!E:E, UTIL!B:B, "", 2), "")), _xlpm.tipoMod, IF(_xlpm.nomeMod="", "", IFERROR(LEFT(_xlpm.nomeMod, FIND(" ", _xlpm.nomeMod)-1), _xlpm.nomeMod)), _xlpm.dimMod, IFERROR(_xlfn.XLOOKUP("*"&_xlpm.modelo&"*", UTIL!D:D, UTIL!K:K, "", 2), IFERROR(_xlfn.XLOOKUP("*"&_xlpm.modelo&"*", UTIL!E:E, UTIL!K:K, "", 2), "")), _xlpm.tipotxt_antigo, IF(_xlpm.ehTrator, "TRATOR", IFERROR(_xlfn.XLOOKUP(_xlpm.chave, _xlpm.fonte, UTIL!BP:BP, "", 0), IFERROR(_xlfn.XLOOKUP("*"&_xlpm.chave&"*", _xlpm.fonte, UTIL!BP:BP, "", 2), "Não encontrado"))), _xlpm.dimtxt_antigo, IFERROR(_xlfn.XLOOKUP(_xlpm.chave, _xlpm.fonte, UTIL!BY:BY, "", 0), IFERROR(_xlfn.XLOOKUP("*"&_xlpm.chave&"*", _xlpm.fonte, UTIL!BY:BY, "", 2), "Não encontrado")), _xlpm.tipotxt, IF(_xlpm.tipoMod<>"", _xlpm.tipoMod, _xlpm.tipotxt_antigo), _xlpm.dimtxt, IF(_xlpm.dimMod<>"", _xlpm.dimMod, _xlpm.dimtxt_antigo), _xlpm.deTxt, IF(L19="CLIENTE", O19, IF(LEFT(L19,4)="http", L19, "MACPONTA AGRO DE "&L19)), _xlpm.paraBase, IF(M19="CLIENTE", P19, M19), _xlpm.paraTxt, IF(LEFT(_xlpm.paraBase,4)="http", _xlpm.paraBase, "MACPONTA AGRO DE "&_xlpm.paraBase), _xlpm.nfParte, IF(LEN(TRIM(I19))=0, "", " -NF "&TRIM(I19)), "- " & _xlpm.tipotxt & ": *" & G19 & "*" & CHAR(13)&CHAR(10) & "- " & _xlpm.dimtxt & CHAR(13)&CHAR(10) & "- *Cliente*: " & J19 & _xlpm.nfParte & CHAR(13)&CHAR(10) & "- *Obs:* " & Q19 & CHAR(13)&CHAR(10) & CHAR(10) & "- *De*: " & _xlpm.deTxt & CHAR(13)&CHAR(10) & "- *Para*: " & _xlpm.paraTxt & CHAR(13)&CHAR(10) & "- *Ida e volta*: +/- " & TEXT(((D19*1.5)/1440),"h:mm") & "h | " & D19 & "km" )} -> - COLHEITADEIRA: *1CQS680ATF0110209*_x000D_ - A:3,98 x C:12,10 x L:3,50-5,43 x P:21.921kg_x000D_ - *Cliente*: DOUGLAS FANCHIN TAQUES FONSECA -NF278835 -NF 45969_x000D_ - *Obs:* VALTINHO 42-99920-3056_x000D_ - *De*: MACPONTA AGRO DE PONTA GROSSA_x000D_ - *Para*: https://maps.app.goo.gl/GfTKV558G2iXHWmg8_x000D_ - *Ida e volta*: +/- 4:22h | 175km
A20: CONCLUIDO | B20: PROPRIO DAF | C20: =IFERROR((D20*1.5)/1440, "?") -> 0.18229167 | D20: 175 | E20: =IFERROR((D20*6),"?") -> 1050 | G20: 1BM6180JKDD001849 | H20: 45968 | I20: 45968 | J20: MANUTENÇÃO → CLIENTE | K20: gustavo.erdmann | L20: PONTA GROSSA | M20: CLIENTE | N20: DE LOJA PARA CLIENTE | O20: MPA | P20: https://maps.app.goo.gl/Yk2FrxveQ1BNpLmN8 | Q20: Cassio | R20: PONTA GROSSA | S20: TRATOR | T20: =IF( OR( IFERROR(FIND("BM",G20),0)>0, IFERROR(FIND("PY",G20),0)>0 ), MID(TRIM(SUBSTITUTE(SUBSTITUTE(G20,CHAR(160),""),CHAR(9),"")),4,5), MID(TRIM(SUBSTITUTE(SUBSTITUTE(G20,CHAR(160),""),CHAR(9),"")),4,4) ) -> 6180J | U20: {=_xlfn.LET( _xlpm.ch, TRIM(SUBSTITUTE(G20,CHAR(160),"")), _xlpm.ehTrator, OR(IFERROR(FIND("BM",_xlpm.ch),0)>0, IFERROR(FIND("PY",_xlpm.ch),0)>0), _xlpm.chave, IF(_xlpm.ehTrator, MID(_xlpm.ch,4,5), MID(_xlpm.ch,4,4)), _xlpm.fonte, IF(LEN(_xlpm.chave)=5, UTIL!BS:BS, UTIL!BR:BR), _xlpm.modelo, TRIM(SUBSTITUTE(T20,CHAR(160),"")), _xlpm.nomeMod, IFERROR(_xlfn.XLOOKUP("*"&_xlpm.modelo&"*", UTIL!D:D, UTIL!B:B, "", 2), IFERROR(_xlfn.XLOOKUP("*"&_xlpm.modelo&"*", UTIL!E:E, UTIL!B:B, "", 2), "")), _xlpm.tipoMod, IF(_xlpm.nomeMod="", "", IFERROR(LEFT(_xlpm.nomeMod, FIND(" ", _xlpm.nomeMod)-1), _xlpm.nomeMod)), _xlpm.dimMod, IFERROR(_xlfn.XLOOKUP("*"&_xlpm.modelo&"*", UTIL!D:D, UTIL!K:K, "", 2), IFERROR(_xlfn.XLOOKUP("*"&_xlpm.modelo&"*", UTIL!E:E, UTIL!K:K, "", 2), "")), _xlpm.tipotxt_antigo, IF(_xlpm.ehTrator, "TRATOR", IFERROR(_xlfn.XLOOKUP(_xlpm.chave, _xlpm.fonte, UTIL!BP:BP, "", 0), IFERROR(_xlfn.XLOOKUP("*"&_xlpm.chave&"*", _xlpm.fonte, UTIL!BP:BP, "", 2), "Não encontrado"))), _xlpm.dimtxt_antigo, IFERROR(_xlfn.XLOOKUP(_xlpm.chave, _xlpm.fonte, UTIL!BY:BY, "", 0), IFERROR(_xlfn.XLOOKUP("*"&_xlpm.chave&"*", _xlpm.fonte, UTIL!BY:BY, "", 2), "Não encontrado")), _xlpm.tipotxt, IF(_xlpm.tipoMod<>"", _xlpm.tipoMod, _xlpm.tipotxt_antigo), _xlpm.dimtxt, IF(_xlpm.dimMod<>"", _xlpm.dimMod, _xlpm.dimtxt_antigo), _xlpm.deTxt, IF(L20="CLIENTE", O20, IF(LEFT(L20,4)="http", L20, "MACPONTA AGRO DE "&L20)), _xlpm.paraBase, IF(M20="CLIENTE", P20, M20), _xlpm.paraTxt, IF(LEFT(_xlpm.paraBase,4)="http", _xlpm.paraBase, "MACPONTA AGRO DE "&_xlpm.paraBase), _xlpm.nfParte, IF(LEN(TRIM(I20))=0, "", " -NF "&TRIM(I20)), "- " & _xlpm.tipotxt & ": *" & G20 & "*" & CHAR(13)&CHAR(10) & "- " & _xlpm.dimtxt & CHAR(13)&CHAR(10) & "- *Cliente*: " & J20 & _xlpm.nfParte & CHAR(13)&CHAR(10) & "- *Obs:* " & Q20 & CHAR(13)&CHAR(10) & CHAR(10) & "- *De*: " & _xlpm.deTxt & CHAR(13)&CHAR(10) & "- *Para*: " & _xlpm.paraTxt & CHAR(13)&CHAR(10) & "- *Ida e volta*: +/- " & TEXT(((D20*1.5)/1440),"h:mm") & "h | " & D20 & "km" )} -> - TRATOR: *1BM6180JKDD001849*_x000D_ - _x000D_ - *Cliente*: MANUTENÇÃO → CLIENTE -NF 45968_x000D_ - *Obs:* Cassio_x000D_ - *De*: MACPONTA AGRO DE PONTA GROSSA_x000D_ - *Para*: https://maps.app.goo.gl/Yk2FrxveQ1BNpLmN8_x000D_ - *Ida e volta*: +/- 4:22h | 175km
